Workbook
Name Z_ABAAE3B4_BD11_4E4B_9CA9_F57AB63E348A_.wvu.PrintArea: Grafik!$A$1:$AC$39
Name Z_ABAAE3B4_BD11_4E4B_9CA9_F57AB63E348A_.wvu.PrintArea: Tracking!$A:$X

Sheet Person
B9: PERSONENDATEN.
B14: Personendaten | F14: Kontakt | I14: Sonstiges | L14: Messungen
B16: Vorname | F16: Strasse | I16: Beruf | L16: Wochentag
B18: Name | F18: PLZ | I18: Erkrankungen | L18: Uhrzeit
B20: Geschlecht (m/w) | F20: Stadt | I20: Sonstiges
B22: Geburtsdatum | F22: Telefon
B24: Alter | C24: =IF(C22="","",DATEDIF(C22,TODAY(),"y")) | F24: Email

Sheet Tracking
J2: Konstante | K2: Gewicht | L2: Größe | M2: Grund- funktion
J7: 40
J8: 11.277845
B9: TRACKING. | J9: -0.72457287 | K9: 7.8112059 | L9: 0.30396975 | O9: m | P9: b
J10: 0.575084 | K10: -0.28815665 | L10: 0.36216425 | M10: 0.5 | O10: 0.48261057 | P10: -0.0061956363
B12: Datum | C12: Alter | E12: Größe | F12: Gewicht | G12: Muskel | H12: KfA | J12: Kinn | K12: Wange | L12: Brust | M12: Trizeps | N12: Rücken | O12: Rippe | P12: Hüfte | Q12: Bauch | R12: Knie | S12: Wade | T12: v. Obers. | U12: h. Obers. | V12: Bizeps | W12: SUMME
E13: cm | F13: kg | G13: kg | H13: % | J13: mm | K13: mm | L13: mm | M13: mm | N13: mm | O13: mm | P13: mm | Q13: mm | R13: mm | S13: mm | T13: mm | U13: mm | V13: mm | W13: mm
C14: =IF(B14="","",DATEDIF(Person!$C$22,B14,"y")) | G14: =IF(F14="","",IF(E14="","",IF(W14="","",F14*(100%-H14/100)))) | H14: =IF(F14="","",IF(E14="","",IF(W14="","",$O$10*(($K$9*F14^$K$10)*($L$9*E14^$L$10)*(ABS(W14-(($J$8*E14^$J$9)*F14^$J$10+$J$7)))^$M$10)+$P$10))) | W14: =IF(J14="","",SUM(J14:S14))
J15: =IF(ISERROR(Grafik!D51),"",Grafik!D51) | K15: =IF(ISERROR(Grafik!E51),"",Grafik!E51) | L15: =IF(ISERROR(Grafik!F51),"",Grafik!F51) | M15: =IF(ISERROR(Grafik!G51),"",Grafik!G51) | N15: =IF(ISERROR(Grafik!H51),"",Grafik!H51) | O15: =IF(ISERROR(Grafik!I51),"",Grafik!I51) | P15: =IF(ISERROR(Grafik!J51),"",Grafik!J51) | Q15: =IF(ISERROR(Grafik!K51),"",Grafik!K51) | ... V15: =IF(ISERROR(Grafik!P51),"",Grafik!P51)
C16: =IF(B16="","",DATEDIF(Person!$C$22,B16,"y")) | G16: =IF(F16="","",IF(E16="","",IF(W16="","",F16*(100%-H16/100)))) | H16: =IF(F16="","",IF(E16="","",IF(W16="","",$O$10*(($K$9*F16^$K$10)*($L$9*E16^$L$10)*(ABS(W16-(($J$8*E16^$J$9)*F16^$J$10+$J$7)))^$M$10)+$P$10))) | W16: =IF(J16="","",SUM(J16:S16))
J17: =IF(ISERROR(Grafik!D53),"",Grafik!D53) | K17: =IF(ISERROR(Grafik!E53),"",Grafik!E53) | L17: =IF(ISERROR(Grafik!F53),"",Grafik!F53) | M17: =IF(ISERROR(Grafik!G53),"",Grafik!G53) | N17: =IF(ISERROR(Grafik!H53),"",Grafik!H53) | O17: =IF(ISERROR(Grafik!I53),"",Grafik!I53) | P17: =IF(ISERROR(Grafik!J53),"",Grafik!J53) | Q17: =IF(ISERROR(Grafik!K53),"",Grafik!K53) | ... V17: =IF(ISERROR(Grafik!P53),"",Grafik!P53)
C18: =IF(B18="","",DATEDIF(Person!$C$22,B18,"y")) | G18: =IF(F18="","",IF(E18="","",IF(W18="","",F18*(100%-H18/100)))) | H18: =IF(F18="","",IF(E18="","",IF(W18="","",$O$10*(($K$9*F18^$K$10)*($L$9*E18^$L$10)*(ABS(W18-(($J$8*E18^$J$9)*F18^$J$10+$J$7)))^$M$10)+$P$10))) | W18: =IF(J18="","",SUM(J18:S18))
J19: =IF(ISERROR(Grafik!D55),"",Grafik!D55) | K19: =IF(ISERROR(Grafik!E55),"",Grafik!E55) | L19: =IF(ISERROR(Grafik!F55),"",Grafik!F55) | M19: =IF(ISERROR(Grafik!G55),"",Grafik!G55) | N19: =IF(ISERROR(Grafik!H55),"",Grafik!H55) | O19: =IF(ISERROR(Grafik!I55),"",Grafik!I55) | P19: =IF(ISERROR(Grafik!J55),"",Grafik!J55) | Q19: =IF(ISERROR(Grafik!K55),"",Grafik!K55) | ... V19: =IF(ISERROR(Grafik!P55),"",Grafik!P55)
C20: =IF(B20="","",DATEDIF(Person!$C$22,B20,"y")) | G20: =IF(F20="","",IF(E20="","",IF(W20="","",F20*(100%-H20/100)))) | H20: =IF(F20="","",IF(E20="","",IF(W20="","",$O$10*(($K$9*F20^$K$10)*($L$9*E20^$L$10)*(ABS(W20-(($J$8*E20^$J$9)*F20^$J$10+$J$7)))^$M$10)+$P$10))) | W20: =IF(J20="","",SUM(J20:S20))
J21: =IF(ISERROR(Grafik!D57),"",Grafik!D57) | K21: =IF(ISERROR(Grafik!E57),"",Grafik!E57) | L21: =IF(ISERROR(Grafik!F57),"",Grafik!F57) | M21: =IF(ISERROR(Grafik!G57),"",Grafik!G57) | N21: =IF(ISERROR(Grafik!H57),"",Grafik!H57) | O21: =IF(ISERROR(Grafik!I57),"",Grafik!I57) | P21: =IF(ISERROR(Grafik!J57),"",Grafik!J57) | Q21: =IF(ISERROR(Grafik!K57),"",Grafik!K57) | ... V21: =IF(ISERROR(Grafik!P57),"",Grafik!P57)
C22: =IF(B22="","",DATEDIF(Person!$C$22,B22,"y")) | G22: =IF(F22="","",IF(E22="","",IF(W22="","",F22*(100%-H22/100)))) | H22: =IF(F22="","",IF(E22="","",IF(W22="","",$O$10*(($K$9*F22^$K$10)*($L$9*E22^$L$10)*(ABS(W22-(($J$8*E22^$J$9)*F22^$J$10+$J$7)))^$M$10)+$P$10))) | W22: =IF(J22="","",SUM(J22:S22))
J23: =IF(ISERROR(Grafik!D59),"",Grafik!D59) | K23: =IF(ISERROR(Grafik!E59),"",Grafik!E59) | L23: =IF(ISERROR(Grafik!F59),"",Grafik!F59) | M23: =IF(ISERROR(Grafik!G59),"",Grafik!G59) | N23: =IF(ISERROR(Grafik!H59),"",Grafik!H59) | O23: =IF(ISERROR(Grafik!I59),"",Grafik!I59) | P23: =IF(ISERROR(Grafik!J59),"",Grafik!J59) | Q23: =IF(ISERROR(Grafik!K59),"",Grafik!K59) | ... V23: =IF(ISERROR(Grafik!P59),"",Grafik!P59)
C24: =IF(B24="","",DATEDIF(Person!$C$22,B24,"y")) | G24: =IF(F24="","",IF(E24="","",IF(W24="","",F24*(100%-H24/100)))) | H24: =IF(F24="","",IF(E24="","",IF(W24="","",$O$10*(($K$9*F24^$K$10)*($L$9*E24^$L$10)*(ABS(W24-(($J$8*E24^$J$9)*F24^$J$10+$J$7)))^$M$10)+$P$10))) | W24: =IF(J24="","",SUM(J24:S24))
J25: =IF(ISERROR(Grafik!D61),"",Grafik!D61) | K25: =IF(ISERROR(Grafik!E61),"",Grafik!E61) | L25: =IF(ISERROR(Grafik!F61),"",Grafik!F61) | M25: =IF(ISERROR(Grafik!G61),"",Grafik!G61) | N25: =IF(ISERROR(Grafik!H61),"",Grafik!H61) | O25: =IF(ISERROR(Grafik!I61),"",Grafik!I61) | P25: =IF(ISERROR(Grafik!J61),"",Grafik!J61) | Q25: =IF(ISERROR(Grafik!K61),"",Grafik!K61) | ... V25: =IF(ISERROR(Grafik!P61),"",Grafik!P61)
C26: =IF(B26="","",DATEDIF(Person!$C$22,B26,"y")) | G26: =IF(F26="","",IF(E26="","",IF(W26="","",F26*(100%-H26/100)))) | H26: =IF(F26="","",IF(E26="","",IF(W26="","",$O$10*(($K$9*F26^$K$10)*($L$9*E26^$L$10)*(ABS(W26-(($J$8*E26^$J$9)*F26^$J$10+$J$7)))^$M$10)+$P$10))) | W26: =IF(J26="","",SUM(J26:S26))
J27: =IF(ISERROR(Grafik!D63),"",Grafik!D63) | K27: =IF(ISERROR(Grafik!E63),"",Grafik!E63) | L27: =IF(ISERROR(Grafik!F63),"",Grafik!F63) | M27: =IF(ISERROR(Grafik!G63),"",Grafik!G63) | N27: =IF(ISERROR(Grafik!H63),"",Grafik!H63) | O27: =IF(ISERROR(Grafik!I63),"",Grafik!I63) | P27: =IF(ISERROR(Grafik!J63),"",Grafik!J63) | Q27: =IF(ISERROR(Grafik!K63),"",Grafik!K63) | ... V27: =IF(ISERROR(Grafik!P63),"",Grafik!P63)
C28: =IF(B28="","",DATEDIF(Person!$C$22,B28,"y")) | G28: =IF(F28="","",IF(E28="","",IF(W28="","",F28*(100%-H28/100)))) | H28: =IF(F28="","",IF(E28="","",IF(W28="","",$O$10*(($K$9*F28^$K$10)*($L$9*E28^$L$10)*(ABS(W28-(($J$8*E28^$J$9)*F28^$J$10+$J$7)))^$M$10)+$P$10))) | W28: =IF(J28="","",SUM(J28:S28))
J29: =IF(ISERROR(Grafik!D65),"",Grafik!D65) | K29: =IF(ISERROR(Grafik!E65),"",Grafik!E65) | L29: =IF(ISERROR(Grafik!F65),"",Grafik!F65) | M29: =IF(ISERROR(Grafik!G65),"",Grafik!G65) | N29: =IF(ISERROR(Grafik!H65),"",Grafik!H65) | O29: =IF(ISERROR(Grafik!I65),"",Grafik!I65) | P29: =IF(ISERROR(Grafik!J65),"",Grafik!J65) | Q29: =IF(ISERROR(Grafik!K65),"",Grafik!K65) | ... V29: =IF(ISERROR(Grafik!P65),"",Grafik!P65)
C30: =IF(B30="","",DATEDIF(Person!$C$22,B30,"y")) | G30: =IF(F30="","",IF(E30="","",IF(W30="","",F30*(100%-H30/100)))) | H30: =IF(F30="","",IF(E30="","",IF(W30="","",$O$10*(($K$9*F30^$K$10)*($L$9*E30^$L$10)*(ABS(W30-(($J$8*E30^$J$9)*F30^$J$10+$J$7)))^$M$10)+$P$10))) | W30: =IF(J30="","",SUM(J30:S30))
J31: =IF(ISERROR(Grafik!D67),"",Grafik!D67) | K31: =IF(ISERROR(Grafik!E67),"",Grafik!E67) | L31: =IF(ISERROR(Grafik!F67),"",Grafik!F67) | M31: =IF(ISERROR(Grafik!G67),"",Grafik!G67) | N31: =IF(ISERROR(Grafik!H67),"",Grafik!H67) | O31: =IF(ISERROR(Grafik!I67),"",Grafik!I67) | P31: =IF(ISERROR(Grafik!J67),"",Grafik!J67) | Q31: =IF(ISERROR(Grafik!K67),"",Grafik!K67) | ... V31: =IF(ISERROR(Grafik!P67),"",Grafik!P67)
C32: =IF(B32="","",DATEDIF(Person!$C$22,B32,"y")) | G32: =IF(F32="","",IF(E32="","",IF(W32="","",F32*(100%-H32/100)))) | H32: =IF(F32="","",IF(E32="","",IF(W32="","",$O$10*(($K$9*F32^$K$10)*($L$9*E32^$L$10)*(ABS(W32-(($J$8*E32^$J$9)*F32^$J$10+$J$7)))^$M$10)+$P$10))) | W32: =IF(J32="","",SUM(J32:S32))
J33: =IF(ISERROR(Grafik!D69),"",Grafik!D69) | K33: =IF(ISERROR(Grafik!E69),"",Grafik!E69) | L33: =IF(ISERROR(Grafik!F69),"",Grafik!F69) | M33: =IF(ISERROR(Grafik!G69),"",Grafik!G69) | N33: =IF(ISERROR(Grafik!H69),"",Grafik!H69) | O33: =IF(ISERROR(Grafik!I69),"",Grafik!I69) | P33: =IF(ISERROR(Grafik!J69),"",Grafik!J69) | Q33: =IF(ISERROR(Grafik!K69),"",Grafik!K69) | ... V33: =IF(ISERROR(Grafik!P69),"",Grafik!P69)
C34: =IF(B34="","",DATEDIF(Person!$C$22,B34,"y")) | G34: =IF(F34="","",IF(E34="","",IF(W34="","",F34*(100%-H34/100)))) | H34: =IF(F34="","",IF(E34="","",IF(W34="","",$O$10*(($K$9*F34^$K$10)*($L$9*E34^$L$10)*(ABS(W34-(($J$8*E34^$J$9)*F34^$J$10+$J$7)))^$M$10)+$P$10))) | W34: =IF(J34="","",SUM(J34:S34))
J35: =IF(ISERROR(Grafik!D71),"",Grafik!D71) | K35: =IF(ISERROR(Grafik!E71),"",Grafik!E71) | L35: =IF(ISERROR(Grafik!F71),"",Grafik!F71) | M35: =IF(ISERROR(Grafik!G71),"",Grafik!G71) | N35: =IF(ISERROR(Grafik!H71),"",Grafik!H71) | O35: =IF(ISERROR(Grafik!I71),"",Grafik!I71) | P35: =IF(ISERROR(Grafik!J71),"",Grafik!J71) | Q35: =IF(ISERROR(Grafik!K71),"",Grafik!K71) | ... V35: =IF(ISERROR(Grafik!P71),"",Grafik!P71)
C36: =IF(B36="","",DATEDIF(Person!$C$22,B36,"y")) | G36: =IF(F36="","",IF(E36="","",IF(W36="","",F36*(100%-H36/100)))) | H36: =IF(F36="","",IF(E36="","",IF(W36="","",$O$10*(($K$9*F36^$K$10)*($L$9*E36^$L$10)*(ABS(W36-(($J$8*E36^$J$9)*F36^$J$10+$J$7)))^$M$10)+$P$10))) | W36: =IF(J36="","",SUM(J36:S36))
J37: =IF(ISERROR(Grafik!D73),"",Grafik!D73) | K37: =IF(ISERROR(Grafik!E73),"",Grafik!E73) | L37: =IF(ISERROR(Grafik!F73),"",Grafik!F73) | M37: =IF(ISERROR(Grafik!G73),"",Grafik!G73) | N37: =IF(ISERROR(Grafik!H73),"",Grafik!H73) | O37: =IF(ISERROR(Grafik!I73),"",Grafik!I73) | P37: =IF(ISERROR(Grafik!J73),"",Grafik!J73) | Q37: =IF(ISERROR(Grafik!K73),"",Grafik!K73) | ... V37: =IF(ISERROR(Grafik!P73),"",Grafik!P73)
C38: =IF(B38="","",DATEDIF(Person!$C$22,B38,"y")) | G38: =IF(F38="","",IF(E38="","",IF(W38="","",F38*(100%-H38/100)))) | H38: =IF(F38="","",IF(E38="","",IF(W38="","",$O$10*(($K$9*F38^$K$10)*($L$9*E38^$L$10)*(ABS(W38-(($J$8*E38^$J$9)*F38^$J$10+$J$7)))^$M$10)+$P$10))) | W38: =IF(J38="","",SUM(J38:S38))
J39: =IF(ISERROR(Grafik!D75),"",Grafik!D75) | K39: =IF(ISERROR(Grafik!E75),"",Grafik!E75) | L39: =IF(ISERROR(Grafik!F75),"",Grafik!F75) | M39: =IF(ISERROR(Grafik!G75),"",Grafik!G75) | N39: =IF(ISERROR(Grafik!H75),"",Grafik!H75) | O39: =IF(ISERROR(Grafik!I75),"",Grafik!I75) | P39: =IF(ISERROR(Grafik!J75),"",Grafik!J75) | Q39: =IF(ISERROR(Grafik!K75),"",Grafik!K75) | ... V39: =IF(ISERROR(Grafik!P75),"",Grafik!P75)
C40: =IF(B40="","",DATEDIF(Person!$C$22,B40,"y")) | G40: =IF(F40="","",IF(E40="","",IF(W40="","",F40*(100%-H40/100)))) | H40: =IF(F40="","",IF(E40="","",IF(W40="","",$O$10*(($K$9*F40^$K$10)*($L$9*E40^$L$10)*(ABS(W40-(($J$8*E40^$J$9)*F40^$J$10+$J$7)))^$M$10)+$P$10))) | W40: =IF(J40="","",SUM(J40:S40))
J41: =IF(ISERROR(Grafik!D77),"",Grafik!D77) | K41: =IF(ISERROR(Grafik!E77),"",Grafik!E77) | L41: =IF(ISERROR(Grafik!F77),"",Grafik!F77) | M41: =IF(ISERROR(Grafik!G77),"",Grafik!G77) | N41: =IF(ISERROR(Grafik!H77),"",Grafik!H77) | O41: =IF(ISERROR(Grafik!I77),"",Grafik!I77) | P41: =IF(ISERROR(Grafik!J77),"",Grafik!J77) | Q41: =IF(ISERROR(Grafik!K77),"",Grafik!K77) | ... V41: =IF(ISERROR(Grafik!P77),"",Grafik!P77)
C42: =IF(B42="","",DATEDIF(Person!$C$22,B42,"y")) | G42: =IF(F42="","",IF(E42="","",IF(W42="","",F42*(100%-H42/100)))) | H42: =IF(F42="","",IF(E42="","",IF(W42="","",$O$10*(($K$9*F42^$K$10)*($L$9*E42^$L$10)*(ABS(W42-(($J$8*E42^$J$9)*F42^$J$10+$J$7)))^$M$10)+$P$10))) | W42: =IF(J42="","",SUM(J42:S42))
J43: =IF(ISERROR(Grafik!D79),"",Grafik!D79) | K43: =IF(ISERROR(Grafik!E79),"",Grafik!E79) | L43: =IF(ISERROR(Grafik!F79),"",Grafik!F79) | M43: =IF(ISERROR(Grafik!G79),"",Grafik!G79) | N43: =IF(ISERROR(Grafik!H79),"",Grafik!H79) | O43: =IF(ISERROR(Grafik!I79),"",Grafik!I79) | P43: =IF(ISERROR(Grafik!J79),"",Grafik!J79) | Q43: =IF(ISERROR(Grafik!K79),"",Grafik!K79) | ... V43: =IF(ISERROR(Grafik!P79),"",Grafik!P79)
C44: =IF(B44="","",DATEDIF(Person!$C$22,B44,"y")) | G44: =IF(F44="","",IF(E44="","",IF(W44="","",F44*(100%-H44/100)))) | H44: =IF(F44="","",IF(E44="","",IF(W44="","",$O$10*(($K$9*F44^$K$10)*($L$9*E44^$L$10)*(ABS(W44-(($J$8*E44^$J$9)*F44^$J$10+$J$7)))^$M$10)+$P$10))) | W44: =IF(J44="","",SUM(J44:S44))
J45: =IF(ISERROR(Grafik!D81),"",Grafik!D81) | K45: =IF(ISERROR(Grafik!E81),"",Grafik!E81) | L45: =IF(ISERROR(Grafik!F81),"",Grafik!F81) | M45: =IF(ISERROR(Grafik!G81),"",Grafik!G81) | N45: =IF(ISERROR(Grafik!H81),"",Grafik!H81) | O45: =IF(ISERROR(Grafik!I81),"",Grafik!I81) | P45: =IF(ISERROR(Grafik!J81),"",Grafik!J81) | Q45: =IF(ISERROR(Grafik!K81),"",Grafik!K81) | ... V45: =IF(ISERROR(Grafik!P81),"",Grafik!P81)
C46: =IF(B46="","",DATEDIF(Person!$C$22,B46,"y")) | G46: =IF(F46="","",IF(E46="","",IF(W46="","",F46*(100%-H46/100)))) | H46: =IF(F46="","",IF(E46="","",IF(W46="","",$O$10*(($K$9*F46^$K$10)*($L$9*E46^$L$10)*(ABS(W46-(($J$8*E46^$J$9)*F46^$J$10+$J$7)))^$M$10)+$P$10))) | W46: =IF(J46="","",SUM(J46:S46))
...

Sheet Grafik
B10: Körperfettmessung - Verlauf
C40: Soll-Wertebereich | R40: Rating
D43: Kinn | E43: Wange | F43: Brust | G43: Trizeps | H43: Schulter- blatt | I43: Rippe | J43: Hüfte | K43: Bauch | L43: Knie | M43: Waden | N43: v. Ober- schenkel | O43: h. Ober- schenkel | P43: Bizeps
B44: Männer | C44: MIN | D44: 1.3 | E44: 1.97 | F44: 0.78 | G44: 1 | H44: 2.1 | I44: 1.23 | J44: 2 | K44: 1.96 | L44: 1.51 | M44: 0.91 | N44: 1.25 | O44: 1.25 | P44: 0.83 | R44: 1 | S44: 2 | T44: 3 | U44: 4 | V44: 5 | W44: 6 | X44: 7 | Y44: 8 | Z44: 9 | AA44: 10 | AB44: 11 | AC44: 12 | AD44: 13
C45: MITTEL | D45: =AVERAGE(D44,D46) -> 1.405 | E45: =AVERAGE(E44,E46) -> 1.985 | F45: =AVERAGE(F44,F46) -> 0.795 | G45: =AVERAGE(G44,G46) -> 1 | H45: =AVERAGE(H44,H46) -> 2.255 | I45: =AVERAGE(I44,I46) -> 1.405 | J45: =AVERAGE(J44,J46) -> 2.15 | K45: =AVERAGE(K44,K46) -> 2.01 | ... P45: =AVERAGE(P44,P46) -> 0.84
C46: MAX | D46: 1.51 | E46: 2 | F46: 0.81 | G46: 1 | H46: 2.41 | I46: 1.58 | J46: 2.3 | K46: 2.06 | L46: 1.74 | M46: 0.99 | N46: 1.4 | O46: 1.4 | P46: 0.85
B47: Frauen | C47: MIN | D47: 0.59 | E47: 0.82 | F47: 0.33 | G47: 1 | H47: 0.74 | I47: 0.6 | J47: 0.64 | K47: 0.71 | L47: 0.58 | M47: 0.82 | N47: 1.69 | O47: 1.69 | P47: 0.41
C48: MITTEL | D48: =AVERAGE(D47,D49) -> 0.655 | E48: =AVERAGE(E47,E49) -> 0.87 | F48: =AVERAGE(F47,F49) -> 0.34 | G48: =AVERAGE(G47,G49) -> 1 | H48: =AVERAGE(H47,H49) -> 0.87 | I48: =AVERAGE(I47,I49) -> 0.705 | J48: =AVERAGE(J47,J49) -> 0.775 | K48: =AVERAGE(K47,K49) -> 0.815 | ... P48: =AVERAGE(P47,P49) -> 0.45
C49: MAX | D49: 0.72 | E49: 0.92 | F49: 0.35 | G49: 1 | H49: 1 | I49: 0.81 | J49: 0.91 | K49: 0.92 | L49: 0.62 | M49: 0.91 | N49: 1.8 | O49: 1.8 | P49: 0.49
D50: =IF(Tracking!J14="","",IF(Person!$C$20="m",ABS((Tracking!J14/4-D$45)),ABS((Tracking!J14/4-D$48)))) | E50: =IF(Tracking!K14="","",IF(Person!$C$20="m",ABS((Tracking!K14/4-E$45)),ABS((Tracking!K14/4-E$48)))) | F50: =IF(Tracking!L14="","",IF(Person!$C$20="m",ABS((Tracking!L14/4-F$45)),ABS((Tracking!L14/4-F$48)))) | G50: =IF(Tracking!M14="","",IF(Person!$C$20="m",ABS((Tracking!M14/4-G$45)),ABS((Tracking!M14/4-G$48)))) | H50: =IF(Tracking!N14="","",IF(Person!$C$20="m",ABS((Tracking!N14/4-H$45)),ABS((Tracking!N14/4-H$48)))) | I50: =IF(Tracking!O14="","",IF(Person!$C$20="m",ABS((Tracking!O14/4-I$45)),ABS((Tracking!O14/4-I$48)))) | J50: =IF(Tracking!P14="","",IF(Person!$C$20="m",ABS((Tracking!P14/4-J$45)),ABS((Tracking!P14/4-J$48)))) | K50: =IF(Tracking!Q14="","",IF(Person!$C$20="m",ABS((Tracking!Q14/4-K$45)),ABS((Tracking!Q14/4-K$48)))) | ... P50: =IF(Tracking!V14="","",IF(Person!$C$20="m",ABS((Tracking!V14/4-P$45)),ABS((Tracking!V14/4-P$48)))) | R50: =IF(ISERROR(LARGE($D50:$P50,R$44)),"",LARGE($D50:$P50,R$44)) | S50: =IF(ISERROR(LARGE($D50:$P50,S$44)),"",LARGE($D50:$P50,S$44)) | T50: =IF(ISERROR(LARGE($D50:$P50,T$44)),"",LARGE($D50:$P50,T$44)) | U50: =IF(ISERROR(LARGE($D50:$P50,U$44)),"",LARGE($D50:$P50,U$44)) | V50: =IF(ISERROR(LARGE($D50:$P50,V$44)),"",LARGE($D50:$P50,V$44)) | W50: =IF(ISERROR(LARGE($D50:$P50,W$44)),"",LARGE($D50:$P50,W$44)) | X50: =IF(ISERROR(LARGE($D50:$P50,X$44)),"",LARGE($D50:$P50,X$44)) | Y50: =IF(ISERROR(LARGE($D50:$P50,Y$44)),"",LARGE($D50:$P50,Y$44)) | ... AD50: =IF(ISERROR(LARGE($D50:$P50,AD$44)),"",LARGE($D50:$P50,AD$44))
D51: =IF(D50="","",IF(D50=$R50,1,IF(D50=$S50,2,IF(D50=$T50,3,IF(D50=$U50,4,IF(D50=$V50,5,IF(D50=$W50,6,IF(D50=$X50,7,IF(D50=$Y50,8,IF(D50=$Z50,9,IF(D50=$AA50,10,IF(D50=$AB50,11,IF(D50=$AC50,12,IF(D50=$AD50,13)))))))))))))) | E51: =IF(E50="","",IF(E50=$R50,1,IF(E50=$S50,2,IF(E50=$T50,3,IF(E50=$U50,4,IF(E50=$V50,5,IF(E50=$W50,6,IF(E50=$X50,7,IF(E50=$Y50,8,IF(E50=$Z50,9,IF(E50=$AA50,10,IF(E50=$AB50,11,IF(E50=$AC50,12,IF(E50=$AD50,13)))))))))))))) | F51: =IF(F50="","",IF(F50=$R50,1,IF(F50=$S50,2,IF(F50=$T50,3,IF(F50=$U50,4,IF(F50=$V50,5,IF(F50=$W50,6,IF(F50=$X50,7,IF(F50=$Y50,8,IF(F50=$Z50,9,IF(F50=$AA50,10,IF(F50=$AB50,11,IF(F50=$AC50,12,IF(F50=$AD50,13)))))))))))))) | G51: =IF(G50="","",IF(G50=$R50,1,IF(G50=$S50,2,IF(G50=$T50,3,IF(G50=$U50,4,IF(G50=$V50,5,IF(G50=$W50,6,IF(G50=$X50,7,IF(G50=$Y50,8,IF(G50=$Z50,9,IF(G50=$AA50,10,IF(G50=$AB50,11,IF(G50=$AC50,12,IF(G50=$AD50,13)))))))))))))) | H51: =IF(H50="","",IF(H50=$R50,1,IF(H50=$S50,2,IF(H50=$T50,3,IF(H50=$U50,4,IF(H50=$V50,5,IF(H50=$W50,6,IF(H50=$X50,7,IF(H50=$Y50,8,IF(H50=$Z50,9,IF(H50=$AA50,10,IF(H50=$AB50,11,IF(H50=$AC50,12,IF(H50=$AD50,13)))))))))))))) | I51: =IF(I50="","",IF(I50=$R50,1,IF(I50=$S50,2,IF(I50=$T50,3,IF(I50=$U50,4,IF(I50=$V50,5,IF(I50=$W50,6,IF(I50=$X50,7,IF(I50=$Y50,8,IF(I50=$Z50,9,IF(I50=$AA50,10,IF(I50=$AB50,11,IF(I50=$AC50,12,IF(I50=$AD50,13)))))))))))))) | J51: =IF(J50="","",IF(J50=$R50,1,IF(J50=$S50,2,IF(J50=$T50,3,IF(J50=$U50,4,IF(J50=$V50,5,IF(J50=$W50,6,IF(J50=$X50,7,IF(J50=$Y50,8,IF(J50=$Z50,9,IF(J50=$AA50,10,IF(J50=$AB50,11,IF(J50=$AC50,12,IF(J50=$AD50,13)))))))))))))) | K51: =IF(K50="","",IF(K50=$R50,1,IF(K50=$S50,2,IF(K50=$T50,3,IF(K50=$U50,4,IF(K50=$V50,5,IF(K50=$W50,6,IF(K50=$X50,7,IF(K50=$Y50,8,IF(K50=$Z50,9,IF(K50=$AA50,10,IF(K50=$AB50,11,IF(K50=$AC50,12,IF(K50=$AD50,13)))))))))))))) | ... P51: =IF(P50="","",IF(P50=$R50,1,IF(P50=$S50,2,IF(P50=$T50,3,IF(P50=$U50,4,IF(P50=$V50,5,IF(P50=$W50,6,IF(P50=$X50,7,IF(P50=$Y50,8,IF(P50=$Z50,9,IF(P50=$AA50,10,IF(P50=$AB50,11,IF(P50=$AC50,12,IF(P50=$AD50,13))))))))))))))
D52: =IF(Tracking!J16="","",IF(Person!$C$20="m",ABS((Tracking!J16/4-D$45)),ABS((Tracking!J16/4-D$48)))) | E52: =IF(Tracking!K16="","",IF(Person!$C$20="m",ABS((Tracking!K16/4-E$45)),ABS((Tracking!K16/4-E$48)))) | F52: =IF(Tracking!L16="","",IF(Person!$C$20="m",ABS((Tracking!L16/4-F$45)),ABS((Tracking!L16/4-F$48)))) | G52: =IF(Tracking!M16="","",IF(Person!$C$20="m",ABS((Tracking!M16/4-G$45)),ABS((Tracking!M16/4-G$48)))) | H52: =IF(Tracking!N16="","",IF(Person!$C$20="m",ABS((Tracking!N16/4-H$45)),ABS((Tracking!N16/4-H$48)))) | I52: =IF(Tracking!O16="","",IF(Person!$C$20="m",ABS((Tracking!O16/4-I$45)),ABS((Tracking!O16/4-I$48)))) | J52: =IF(Tracking!P16="","",IF(Person!$C$20="m",ABS((Tracking!P16/4-J$45)),ABS((Tracking!P16/4-J$48)))) | K52: =IF(Tracking!Q16="","",IF(Person!$C$20="m",ABS((Tracking!Q16/4-K$45)),ABS((Tracking!Q16/4-K$48)))) | ... P52: =IF(Tracking!V16="","",IF(Person!$C$20="m",ABS((Tracking!V16/4-P$45)),ABS((Tracking!V16/4-P$48)))) | R52: =IF(ISERROR(LARGE($D52:$P52,R$44)),"",LARGE($D52:$P52,R$44)) | S52: =IF(ISERROR(LARGE($D52:$P52,S$44)),"",LARGE($D52:$P52,S$44)) | T52: =IF(ISERROR(LARGE($D52:$P52,T$44)),"",LARGE($D52:$P52,T$44)) | U52: =IF(ISERROR(LARGE($D52:$P52,U$44)),"",LARGE($D52:$P52,U$44)) | V52: =IF(ISERROR(LARGE($D52:$P52,V$44)),"",LARGE($D52:$P52,V$44)) | W52: =IF(ISERROR(LARGE($D52:$P52,W$44)),"",LARGE($D52:$P52,W$44)) | X52: =IF(ISERROR(LARGE($D52:$P52,X$44)),"",LARGE($D52:$P52,X$44)) | Y52: =IF(ISERROR(LARGE($D52:$P52,Y$44)),"",LARGE($D52:$P52,Y$44)) | ... AD52: =IF(ISERROR(LARGE($D52:$P52,AD$44)),"",LARGE($D52:$P52,AD$44))
D53: =IF(D52="","",IF(D52=$R52,1,IF(D52=$S52,2,IF(D52=$T52,3,IF(D52=$U52,4,IF(D52=$V52,5,IF(D52=$W52,6,IF(D52=$X52,7,IF(D52=$Y52,8,IF(D52=$Z52,9,IF(D52=$AA52,10,IF(D52=$AB52,11,IF(D52=$AC52,12,IF(D52=$AD52,13)))))))))))))) | E53: =IF(E52="","",IF(E52=$R52,1,IF(E52=$S52,2,IF(E52=$T52,3,IF(E52=$U52,4,IF(E52=$V52,5,IF(E52=$W52,6,IF(E52=$X52,7,IF(E52=$Y52,8,IF(E52=$Z52,9,IF(E52=$AA52,10,IF(E52=$AB52,11,IF(E52=$AC52,12,IF(E52=$AD52,13)))))))))))))) | F53: =IF(F52="","",IF(F52=$R52,1,IF(F52=$S52,2,IF(F52=$T52,3,IF(F52=$U52,4,IF(F52=$V52,5,IF(F52=$W52,6,IF(F52=$X52,7,IF(F52=$Y52,8,IF(F52=$Z52,9,IF(F52=$AA52,10,IF(F52=$AB52,11,IF(F52=$AC52,12,IF(F52=$AD52,13)))))))))))))) | G53: =IF(G52="","",IF(G52=$R52,1,IF(G52=$S52,2,IF(G52=$T52,3,IF(G52=$U52,4,IF(G52=$V52,5,IF(G52=$W52,6,IF(G52=$X52,7,IF(G52=$Y52,8,IF(G52=$Z52,9,IF(G52=$AA52,10,IF(G52=$AB52,11,IF(G52=$AC52,12,IF(G52=$AD52,13)))))))))))))) | H53: =IF(H52="","",IF(H52=$R52,1,IF(H52=$S52,2,IF(H52=$T52,3,IF(H52=$U52,4,IF(H52=$V52,5,IF(H52=$W52,6,IF(H52=$X52,7,IF(H52=$Y52,8,IF(H52=$Z52,9,IF(H52=$AA52,10,IF(H52=$AB52,11,IF(H52=$AC52,12,IF(H52=$AD52,13)))))))))))))) | I53: =IF(I52="","",IF(I52=$R52,1,IF(I52=$S52,2,IF(I52=$T52,3,IF(I52=$U52,4,IF(I52=$V52,5,IF(I52=$W52,6,IF(I52=$X52,7,IF(I52=$Y52,8,IF(I52=$Z52,9,IF(I52=$AA52,10,IF(I52=$AB52,11,IF(I52=$AC52,12,IF(I52=$AD52,13)))))))))))))) | J53: =IF(J52="","",IF(J52=$R52,1,IF(J52=$S52,2,IF(J52=$T52,3,IF(J52=$U52,4,IF(J52=$V52,5,IF(J52=$W52,6,IF(J52=$X52,7,IF(J52=$Y52,8,IF(J52=$Z52,9,IF(J52=$AA52,10,IF(J52=$AB52,11,IF(J52=$AC52,12,IF(J52=$AD52,13)))))))))))))) | K53: =IF(K52="","",IF(K52=$R52,1,IF(K52=$S52,2,IF(K52=$T52,3,IF(K52=$U52,4,IF(K52=$V52,5,IF(K52=$W52,6,IF(K52=$X52,7,IF(K52=$Y52,8,IF(K52=$Z52,9,IF(K52=$AA52,10,IF(K52=$AB52,11,IF(K52=$AC52,12,IF(K52=$AD52,13)))))))))))))) | ... P53: =IF(P52="","",IF(P52=$R52,1,IF(P52=$S52,2,IF(P52=$T52,3,IF(P52=$U52,4,IF(P52=$V52,5,IF(P52=$W52,6,IF(P52=$X52,7,IF(P52=$Y52,8,IF(P52=$Z52,9,IF(P52=$AA52,10,IF(P52=$AB52,11,IF(P52=$AC52,12,IF(P52=$AD52,13))))))))))))))
D54: =IF(Tracking!J18="","",IF(Person!$C$20="m",ABS((Tracking!J18/4-D$45)),ABS((Tracking!J18/4-D$48)))) | E54: =IF(Tracking!K18="","",IF(Person!$C$20="m",ABS((Tracking!K18/4-E$45)),ABS((Tracking!K18/4-E$48)))) | F54: =IF(Tracking!L18="","",IF(Person!$C$20="m",ABS((Tracking!L18/4-F$45)),ABS((Tracking!L18/4-F$48)))) | G54: =IF(Tracking!M18="","",IF(Person!$C$20="m",ABS((Tracking!M18/4-G$45)),ABS((Tracking!M18/4-G$48)))) | H54: =IF(Tracking!N18="","",IF(Person!$C$20="m",ABS((Tracking!N18/4-H$45)),ABS((Tracking!N18/4-H$48)))) | I54: =IF(Tracking!O18="","",IF(Person!$C$20="m",ABS((Tracking!O18/4-I$45)),ABS((Tracking!O18/4-I$48)))) | J54: =IF(Tracking!P18="","",IF(Person!$C$20="m",ABS((Tracking!P18/4-J$45)),ABS((Tracking!P18/4-J$48)))) | K54: =IF(Tracking!Q18="","",IF(Person!$C$20="m",ABS((Tracking!Q18/4-K$45)),ABS((Tracking!Q18/4-K$48)))) | ... P54: =IF(Tracking!V18="","",IF(Person!$C$20="m",ABS((Tracking!V18/4-P$45)),ABS((Tracking!V18/4-P$48)))) | R54: =IF(ISERROR(LARGE($D54:$P54,R$44)),"",LARGE($D54:$P54,R$44)) | S54: =IF(ISERROR(LARGE($D54:$P54,S$44)),"",LARGE($D54:$P54,S$44)) | T54: =IF(ISERROR(LARGE($D54:$P54,T$44)),"",LARGE($D54:$P54,T$44)) | U54: =IF(ISERROR(LARGE($D54:$P54,U$44)),"",LARGE($D54:$P54,U$44)) | V54: =IF(ISERROR(LARGE($D54:$P54,V$44)),"",LARGE($D54:$P54,V$44)) | W54: =IF(ISERROR(LARGE($D54:$P54,W$44)),"",LARGE($D54:$P54,W$44)) | X54: =IF(ISERROR(LARGE($D54:$P54,X$44)),"",LARGE($D54:$P54,X$44)) | Y54: =IF(ISERROR(LARGE($D54:$P54,Y$44)),"",LARGE($D54:$P54,Y$44)) | ... AD54: =IF(ISERROR(LARGE($D54:$P54,AD$44)),"",LARGE($D54:$P54,AD$44))
D55: =IF(D54="","",IF(D54=$R54,1,IF(D54=$S54,2,IF(D54=$T54,3,IF(D54=$U54,4,IF(D54=$V54,5,IF(D54=$W54,6,IF(D54=$X54,7,IF(D54=$Y54,8,IF(D54=$Z54,9,IF(D54=$AA54,10,IF(D54=$AB54,11,IF(D54=$AC54,12,IF(D54=$AD54,13)))))))))))))) | E55: =IF(E54="","",IF(E54=$R54,1,IF(E54=$S54,2,IF(E54=$T54,3,IF(E54=$U54,4,IF(E54=$V54,5,IF(E54=$W54,6,IF(E54=$X54,7,IF(E54=$Y54,8,IF(E54=$Z54,9,IF(E54=$AA54,10,IF(E54=$AB54,11,IF(E54=$AC54,12,IF(E54=$AD54,13)))))))))))))) | F55: =IF(F54="","",IF(F54=$R54,1,IF(F54=$S54,2,IF(F54=$T54,3,IF(F54=$U54,4,IF(F54=$V54,5,IF(F54=$W54,6,IF(F54=$X54,7,IF(F54=$Y54,8,IF(F54=$Z54,9,IF(F54=$AA54,10,IF(F54=$AB54,11,IF(F54=$AC54,12,IF(F54=$AD54,13)))))))))))))) | G55: =IF(G54="","",IF(G54=$R54,1,IF(G54=$S54,2,IF(G54=$T54,3,IF(G54=$U54,4,IF(G54=$V54,5,IF(G54=$W54,6,IF(G54=$X54,7,IF(G54=$Y54,8,IF(G54=$Z54,9,IF(G54=$AA54,10,IF(G54=$AB54,11,IF(G54=$AC54,12,IF(G54=$AD54,13)))))))))))))) | H55: =IF(H54="","",IF(H54=$R54,1,IF(H54=$S54,2,IF(H54=$T54,3,IF(H54=$U54,4,IF(H54=$V54,5,IF(H54=$W54,6,IF(H54=$X54,7,IF(H54=$Y54,8,IF(H54=$Z54,9,IF(H54=$AA54,10,IF(H54=$AB54,11,IF(H54=$AC54,12,IF(H54=$AD54,13)))))))))))))) | I55: =IF(I54="","",IF(I54=$R54,1,IF(I54=$S54,2,IF(I54=$T54,3,IF(I54=$U54,4,IF(I54=$V54,5,IF(I54=$W54,6,IF(I54=$X54,7,IF(I54=$Y54,8,IF(I54=$Z54,9,IF(I54=$AA54,10,IF(I54=$AB54,11,IF(I54=$AC54,12,IF(I54=$AD54,13)))))))))))))) | J55: =IF(J54="","",IF(J54=$R54,1,IF(J54=$S54,2,IF(J54=$T54,3,IF(J54=$U54,4,IF(J54=$V54,5,IF(J54=$W54,6,IF(J54=$X54,7,IF(J54=$Y54,8,IF(J54=$Z54,9,IF(J54=$AA54,10,IF(J54=$AB54,11,IF(J54=$AC54,12,IF(J54=$AD54,13)))))))))))))) | K55: =IF(K54="","",IF(K54=$R54,1,IF(K54=$S54,2,IF(K54=$T54,3,IF(K54=$U54,4,IF(K54=$V54,5,IF(K54=$W54,6,IF(K54=$X54,7,IF(K54=$Y54,8,IF(K54=$Z54,9,IF(K54=$AA54,10,IF(K54=$AB54,11,IF(K54=$AC54,12,IF(K54=$AD54,13)))))))))))))) | ... P55: =IF(P54="","",IF(P54=$R54,1,IF(P54=$S54,2,IF(P54=$T54,3,IF(P54=$U54,4,IF(P54=$V54,5,IF(P54=$W54,6,IF(P54=$X54,7,IF(P54=$Y54,8,IF(P54=$Z54,9,IF(P54=$AA54,10,IF(P54=$AB54,11,IF(P54=$AC54,12,IF(P54=$AD54,13))))))))))))))
D56: =IF(Tracking!J20="","",IF(Person!$C$20="m",ABS((Tracking!J20/4-D$45)),ABS((Tracking!J20/4-D$48)))) | E56: =IF(Tracking!K20="","",IF(Person!$C$20="m",ABS((Tracking!K20/4-E$45)),ABS((Tracking!K20/4-E$48)))) | F56: =IF(Tracking!L20="","",IF(Person!$C$20="m",ABS((Tracking!L20/4-F$45)),ABS((Tracking!L20/4-F$48)))) | G56: =IF(Tracking!M20="","",IF(Person!$C$20="m",ABS((Tracking!M20/4-G$45)),ABS((Tracking!M20/4-G$48)))) | H56: =IF(Tracking!N20="","",IF(Person!$C$20="m",ABS((Tracking!N20/4-H$45)),ABS((Tracking!N20/4-H$48)))) | I56: =IF(Tracking!O20="","",IF(Person!$C$20="m",ABS((Tracking!O20/4-I$45)),ABS((Tracking!O20/4-I$48)))) | J56: =IF(Tracking!P20="","",IF(Person!$C$20="m",ABS((Tracking!P20/4-J$45)),ABS((Tracking!P20/4-J$48)))) | K56: =IF(Tracking!Q20="","",IF(Person!$C$20="m",ABS((Tracking!Q20/4-K$45)),ABS((Tracking!Q20/4-K$48)))) | ... P56: =IF(Tracking!V20="","",IF(Person!$C$20="m",ABS((Tracking!V20/4-P$45)),ABS((Tracking!V20/4-P$48)))) | R56: =IF(ISERROR(LARGE($D56:$P56,R$44)),"",LARGE($D56:$P56,R$44)) | S56: =IF(ISERROR(LARGE($D56:$P56,S$44)),"",LARGE($D56:$P56,S$44)) | T56: =IF(ISERROR(LARGE($D56:$P56,T$44)),"",LARGE($D56:$P56,T$44)) | U56: =IF(ISERROR(LARGE($D56:$P56,U$44)),"",LARGE($D56:$P56,U$44)) | V56: =IF(ISERROR(LARGE($D56:$P56,V$44)),"",LARGE($D56:$P56,V$44)) | W56: =IF(ISERROR(LARGE($D56:$P56,W$44)),"",LARGE($D56:$P56,W$44)) | X56: =IF(ISERROR(LARGE($D56:$P56,X$44)),"",LARGE($D56:$P56,X$44)) | Y56: =IF(ISERROR(LARGE($D56:$P56,Y$44)),"",LARGE($D56:$P56,Y$44)) | ... AD56: =IF(ISERROR(LARGE($D56:$P56,AD$44)),"",LARGE($D56:$P56,AD$44))
D57: =IF(D56="","",IF(D56=$R56,1,IF(D56=$S56,2,IF(D56=$T56,3,IF(D56=$U56,4,IF(D56=$V56,5,IF(D56=$W56,6,IF(D56=$X56,7,IF(D56=$Y56,8,IF(D56=$Z56,9,IF(D56=$AA56,10,IF(D56=$AB56,11,IF(D56=$AC56,12,IF(D56=$AD56,13)))))))))))))) | E57: =IF(E56="","",IF(E56=$R56,1,IF(E56=$S56,2,IF(E56=$T56,3,IF(E56=$U56,4,IF(E56=$V56,5,IF(E56=$W56,6,IF(E56=$X56,7,IF(E56=$Y56,8,IF(E56=$Z56,9,IF(E56=$AA56,10,IF(E56=$AB56,11,IF(E56=$AC56,12,IF(E56=$AD56,13)))))))))))))) | F57: =IF(F56="","",IF(F56=$R56,1,IF(F56=$S56,2,IF(F56=$T56,3,IF(F56=$U56,4,IF(F56=$V56,5,IF(F56=$W56,6,IF(F56=$X56,7,IF(F56=$Y56,8,IF(F56=$Z56,9,IF(F56=$AA56,10,IF(F56=$AB56,11,IF(F56=$AC56,12,IF(F56=$AD56,13)))))))))))))) | G57: =IF(G56="","",IF(G56=$R56,1,IF(G56=$S56,2,IF(G56=$T56,3,IF(G56=$U56,4,IF(G56=$V56,5,IF(G56=$W56,6,IF(G56=$X56,7,IF(G56=$Y56,8,IF(G56=$Z56,9,IF(G56=$AA56,10,IF(G56=$AB56,11,IF(G56=$AC56,12,IF(G56=$AD56,13)))))))))))))) | H57: =IF(H56="","",IF(H56=$R56,1,IF(H56=$S56,2,IF(H56=$T56,3,IF(H56=$U56,4,IF(H56=$V56,5,IF(H56=$W56,6,IF(H56=$X56,7,IF(H56=$Y56,8,IF(H56=$Z56,9,IF(H56=$AA56,10,IF(H56=$AB56,11,IF(H56=$AC56,12,IF(H56=$AD56,13)))))))))))))) | I57: =IF(I56="","",IF(I56=$R56,1,IF(I56=$S56,2,IF(I56=$T56,3,IF(I56=$U56,4,IF(I56=$V56,5,IF(I56=$W56,6,IF(I56=$X56,7,IF(I56=$Y56,8,IF(I56=$Z56,9,IF(I56=$AA56,10,IF(I56=$AB56,11,IF(I56=$AC56,12,IF(I56=$AD56,13)))))))))))))) | J57: =IF(J56="","",IF(J56=$R56,1,IF(J56=$S56,2,IF(J56=$T56,3,IF(J56=$U56,4,IF(J56=$V56,5,IF(J56=$W56,6,IF(J56=$X56,7,IF(J56=$Y56,8,IF(J56=$Z56,9,IF(J56=$AA56,10,IF(J56=$AB56,11,IF(J56=$AC56,12,IF(J56=$AD56,13)))))))))))))) | K57: =IF(K56="","",IF(K56=$R56,1,IF(K56=$S56,2,IF(K56=$T56,3,IF(K56=$U56,4,IF(K56=$V56,5,IF(K56=$W56,6,IF(K56=$X56,7,IF(K56=$Y56,8,IF(K56=$Z56,9,IF(K56=$AA56,10,IF(K56=$AB56,11,IF(K56=$AC56,12,IF(K56=$AD56,13)))))))))))))) | ... P57: =IF(P56="","",IF(P56=$R56,1,IF(P56=$S56,2,IF(P56=$T56,3,IF(P56=$U56,4,IF(P56=$V56,5,IF(P56=$W56,6,IF(P56=$X56,7,IF(P56=$Y56,8,IF(P56=$Z56,9,IF(P56=$AA56,10,IF(P56=$AB56,11,IF(P56=$AC56,12,IF(P56=$AD56,13))))))))))))))
D58: =IF(Tracking!J22="","",IF(Person!$C$20="m",ABS((Tracking!J22/4-D$45)),ABS((Tracking!J22/4-D$48)))) | E58: =IF(Tracking!K22="","",IF(Person!$C$20="m",ABS((Tracking!K22/4-E$45)),ABS((Tracking!K22/4-E$48)))) | F58: =IF(Tracking!L22="","",IF(Person!$C$20="m",ABS((Tracking!L22/4-F$45)),ABS((Tracking!L22/4-F$48)))) | G58: =IF(Tracking!M22="","",IF(Person!$C$20="m",ABS((Tracking!M22/4-G$45)),ABS((Tracking!M22/4-G$48)))) | H58: =IF(Tracking!N22="","",IF(Person!$C$20="m",ABS((Tracking!N22/4-H$45)),ABS((Tracking!N22/4-H$48)))) | I58: =IF(Tracking!O22="","",IF(Person!$C$20="m",ABS((Tracking!O22/4-I$45)),ABS((Tracking!O22/4-I$48)))) | J58: =IF(Tracking!P22="","",IF(Person!$C$20="m",ABS((Tracking!P22/4-J$45)),ABS((Tracking!P22/4-J$48)))) | K58: =IF(Tracking!Q22="","",IF(Person!$C$20="m",ABS((Tracking!Q22/4-K$45)),ABS((Tracking!Q22/4-K$48)))) | ... P58: =IF(Tracking!V22="","",IF(Person!$C$20="m",ABS((Tracking!V22/4-P$45)),ABS((Tracking!V22/4-P$48)))) | R58: =IF(ISERROR(LARGE($D58:$P58,R$44)),"",LARGE($D58:$P58,R$44)) | S58: =IF(ISERROR(LARGE($D58:$P58,S$44)),"",LARGE($D58:$P58,S$44)) | T58: =IF(ISERROR(LARGE($D58:$P58,T$44)),"",LARGE($D58:$P58,T$44)) | U58: =IF(ISERROR(LARGE($D58:$P58,U$44)),"",LARGE($D58:$P58,U$44)) | V58: =IF(ISERROR(LARGE($D58:$P58,V$44)),"",LARGE($D58:$P58,V$44)) | W58: =IF(ISERROR(LARGE($D58:$P58,W$44)),"",LARGE($D58:$P58,W$44)) | X58: =IF(ISERROR(LARGE($D58:$P58,X$44)),"",LARGE($D58:$P58,X$44)) | Y58: =IF(ISERROR(LARGE($D58:$P58,Y$44)),"",LARGE($D58:$P58,Y$44)) | ... AD58: =IF(ISERROR(LARGE($D58:$P58,AD$44)),"",LARGE($D58:$P58,AD$44))
D59: =IF(D58="","",IF(D58=$R58,1,IF(D58=$S58,2,IF(D58=$T58,3,IF(D58=$U58,4,IF(D58=$V58,5,IF(D58=$W58,6,IF(D58=$X58,7,IF(D58=$Y58,8,IF(D58=$Z58,9,IF(D58=$AA58,10,IF(D58=$AB58,11,IF(D58=$AC58,12,IF(D58=$AD58,13)))))))))))))) | E59: =IF(E58="","",IF(E58=$R58,1,IF(E58=$S58,2,IF(E58=$T58,3,IF(E58=$U58,4,IF(E58=$V58,5,IF(E58=$W58,6,IF(E58=$X58,7,IF(E58=$Y58,8,IF(E58=$Z58,9,IF(E58=$AA58,10,IF(E58=$AB58,11,IF(E58=$AC58,12,IF(E58=$AD58,13)))))))))))))) | F59: =IF(F58="","",IF(F58=$R58,1,IF(F58=$S58,2,IF(F58=$T58,3,IF(F58=$U58,4,IF(F58=$V58,5,IF(F58=$W58,6,IF(F58=$X58,7,IF(F58=$Y58,8,IF(F58=$Z58,9,IF(F58=$AA58,10,IF(F58=$AB58,11,IF(F58=$AC58,12,IF(F58=$AD58,13)))))))))))))) | G59: =IF(G58="","",IF(G58=$R58,1,IF(G58=$S58,2,IF(G58=$T58,3,IF(G58=$U58,4,IF(G58=$V58,5,IF(G58=$W58,6,IF(G58=$X58,7,IF(G58=$Y58,8,IF(G58=$Z58,9,IF(G58=$AA58,10,IF(G58=$AB58,11,IF(G58=$AC58,12,IF(G58=$AD58,13)))))))))))))) | H59: =IF(H58="","",IF(H58=$R58,1,IF(H58=$S58,2,IF(H58=$T58,3,IF(H58=$U58,4,IF(H58=$V58,5,IF(H58=$W58,6,IF(H58=$X58,7,IF(H58=$Y58,8,IF(H58=$Z58,9,IF(H58=$AA58,10,IF(H58=$AB58,11,IF(H58=$AC58,12,IF(H58=$AD58,13)))))))))))))) | I59: =IF(I58="","",IF(I58=$R58,1,IF(I58=$S58,2,IF(I58=$T58,3,IF(I58=$U58,4,IF(I58=$V58,5,IF(I58=$W58,6,IF(I58=$X58,7,IF(I58=$Y58,8,IF(I58=$Z58,9,IF(I58=$AA58,10,IF(I58=$AB58,11,IF(I58=$AC58,12,IF(I58=$AD58,13)))))))))))))) | J59: =IF(J58="","",IF(J58=$R58,1,IF(J58=$S58,2,IF(J58=$T58,3,IF(J58=$U58,4,IF(J58=$V58,5,IF(J58=$W58,6,IF(J58=$X58,7,IF(J58=$Y58,8,IF(J58=$Z58,9,IF(J58=$AA58,10,IF(J58=$AB58,11,IF(J58=$AC58,12,IF(J58=$AD58,13)))))))))))))) | K59: =IF(K58="","",IF(K58=$R58,1,IF(K58=$S58,2,IF(K58=$T58,3,IF(K58=$U58,4,IF(K58=$V58,5,IF(K58=$W58,6,IF(K58=$X58,7,IF(K58=$Y58,8,IF(K58=$Z58,9,IF(K58=$AA58,10,IF(K58=$AB58,11,IF(K58=$AC58,12,IF(K58=$AD58,13)))))))))))))) | ... P59: =IF(P58="","",IF(P58=$R58,1,IF(P58=$S58,2,IF(P58=$T58,3,IF(P58=$U58,4,IF(P58=$V58,5,IF(P58=$W58,6,IF(P58=$X58,7,IF(P58=$Y58,8,IF(P58=$Z58,9,IF(P58=$AA58,10,IF(P58=$AB58,11,IF(P58=$AC58,12,IF(P58=$AD58,13))))))))))))))
D60: =IF(Tracking!J24="","",IF(Person!$C$20="m",ABS((Tracking!J24/4-D$45)),ABS((Tracking!J24/4-D$48)))) | E60: =IF(Tracking!K24="","",IF(Person!$C$20="m",ABS((Tracking!K24/4-E$45)),ABS((Tracking!K24/4-E$48)))) | F60: =IF(Tracking!L24="","",IF(Person!$C$20="m",ABS((Tracking!L24/4-F$45)),ABS((Tracking!L24/4-F$48)))) | G60: =IF(Tracking!M24="","",IF(Person!$C$20="m",ABS((Tracking!M24/4-G$45)),ABS((Tracking!M24/4-G$48)))) | H60: =IF(Tracking!N24="","",IF(Person!$C$20="m",ABS((Tracking!N24/4-H$45)),ABS((Tracking!N24/4-H$48)))) | I60: =IF(Tracking!O24="","",IF(Person!$C$20="m",ABS((Tracking!O24/4-I$45)),ABS((Tracking!O24/4-I$48)))) | J60: =IF(Tracking!P24="","",IF(Person!$C$20="m",ABS((Tracking!P24/4-J$45)),ABS((Tracking!P24/4-J$48)))) | K60: =IF(Tracking!Q24="","",IF(Person!$C$20="m",ABS((Tracking!Q24/4-K$45)),ABS((Tracking!Q24/4-K$48)))) | ... P60: =IF(Tracking!V24="","",IF(Person!$C$20="m",ABS((Tracking!V24/4-P$45)),ABS((Tracking!V24/4-P$48)))) | R60: =IF(ISERROR(LARGE($D60:$P60,R$44)),"",LARGE($D60:$P60,R$44)) | S60: =IF(ISERROR(LARGE($D60:$P60,S$44)),"",LARGE($D60:$P60,S$44)) | T60: =IF(ISERROR(LARGE($D60:$P60,T$44)),"",LARGE($D60:$P60,T$44)) | U60: =IF(ISERROR(LARGE($D60:$P60,U$44)),"",LARGE($D60:$P60,U$44)) | V60: =IF(ISERROR(LARGE($D60:$P60,V$44)),"",LARGE($D60:$P60,V$44)) | W60: =IF(ISERROR(LARGE($D60:$P60,W$44)),"",LARGE($D60:$P60,W$44)) | X60: =IF(ISERROR(LARGE($D60:$P60,X$44)),"",LARGE($D60:$P60,X$44)) | Y60: =IF(ISERROR(LARGE($D60:$P60,Y$44)),"",LARGE($D60:$P60,Y$44)) | ... AD60: =IF(ISERROR(LARGE($D60:$P60,AD$44)),"",LARGE($D60:$P60,AD$44))
D61: =IF(D60="","",IF(D60=$R60,1,IF(D60=$S60,2,IF(D60=$T60,3,IF(D60=$U60,4,IF(D60=$V60,5,IF(D60=$W60,6,IF(D60=$X60,7,IF(D60=$Y60,8,IF(D60=$Z60,9,IF(D60=$AA60,10,IF(D60=$AB60,11,IF(D60=$AC60,12,IF(D60=$AD60,13)))))))))))))) | E61: =IF(E60="","",IF(E60=$R60,1,IF(E60=$S60,2,IF(E60=$T60,3,IF(E60=$U60,4,IF(E60=$V60,5,IF(E60=$W60,6,IF(E60=$X60,7,IF(E60=$Y60,8,IF(E60=$Z60,9,IF(E60=$AA60,10,IF(E60=$AB60,11,IF(E60=$AC60,12,IF(E60=$AD60,13)))))))))))))) | F61: =IF(F60="","",IF(F60=$R60,1,IF(F60=$S60,2,IF(F60=$T60,3,IF(F60=$U60,4,IF(F60=$V60,5,IF(F60=$W60,6,IF(F60=$X60,7,IF(F60=$Y60,8,IF(F60=$Z60,9,IF(F60=$AA60,10,IF(F60=$AB60,11,IF(F60=$AC60,12,IF(F60=$AD60,13)))))))))))))) | G61: =IF(G60="","",IF(G60=$R60,1,IF(G60=$S60,2,IF(G60=$T60,3,IF(G60=$U60,4,IF(G60=$V60,5,IF(G60=$W60,6,IF(G60=$X60,7,IF(G60=$Y60,8,IF(G60=$Z60,9,IF(G60=$AA60,10,IF(G60=$AB60,11,IF(G60=$AC60,12,IF(G60=$AD60,13)))))))))))))) | H61: =IF(H60="","",IF(H60=$R60,1,IF(H60=$S60,2,IF(H60=$T60,3,IF(H60=$U60,4,IF(H60=$V60,5,IF(H60=$W60,6,IF(H60=$X60,7,IF(H60=$Y60,8,IF(H60=$Z60,9,IF(H60=$AA60,10,IF(H60=$AB60,11,IF(H60=$AC60,12,IF(H60=$AD60,13)))))))))))))) | I61: =IF(I60="","",IF(I60=$R60,1,IF(I60=$S60,2,IF(I60=$T60,3,IF(I60=$U60,4,IF(I60=$V60,5,IF(I60=$W60,6,IF(I60=$X60,7,IF(I60=$Y60,8,IF(I60=$Z60,9,IF(I60=$AA60,10,IF(I60=$AB60,11,IF(I60=$AC60,12,IF(I60=$AD60,13)))))))))))))) | J61: =IF(J60="","",IF(J60=$R60,1,IF(J60=$S60,2,IF(J60=$T60,3,IF(J60=$U60,4,IF(J60=$V60,5,IF(J60=$W60,6,IF(J60=$X60,7,IF(J60=$Y60,8,IF(J60=$Z60,9,IF(J60=$AA60,10,IF(J60=$AB60,11,IF(J60=$AC60,12,IF(J60=$AD60,13)))))))))))))) | K61: =IF(K60="","",IF(K60=$R60,1,IF(K60=$S60,2,IF(K60=$T60,3,IF(K60=$U60,4,IF(K60=$V60,5,IF(K60=$W60,6,IF(K60=$X60,7,IF(K60=$Y60,8,IF(K60=$Z60,9,IF(K60=$AA60,10,IF(K60=$AB60,11,IF(K60=$AC60,12,IF(K60=$AD60,13)))))))))))))) | ... P61: =IF(P60="","",IF(P60=$R60,1,IF(P60=$S60,2,IF(P60=$T60,3,IF(P60=$U60,4,IF(P60=$V60,5,IF(P60=$W60,6,IF(P60=$X60,7,IF(P60=$Y60,8,IF(P60=$Z60,9,IF(P60=$AA60,10,IF(P60=$AB60,11,IF(P60=$AC60,12,IF(P60=$AD60,13))))))))))))))
D62: =IF(Tracking!J26="","",IF(Person!$C$20="m",ABS((Tracking!J26/4-D$45)),ABS((Tracking!J26/4-D$48)))) | E62: =IF(Tracking!K26="","",IF(Person!$C$20="m",ABS((Tracking!K26/4-E$45)),ABS((Tracking!K26/4-E$48)))) | F62: =IF(Tracking!L26="","",IF(Person!$C$20="m",ABS((Tracking!L26/4-F$45)),ABS((Tracking!L26/4-F$48)))) | G62: =IF(Tracking!M26="","",IF(Person!$C$20="m",ABS((Tracking!M26/4-G$45)),ABS((Tracking!M26/4-G$48)))) | H62: =IF(Tracking!N26="","",IF(Person!$C$20="m",ABS((Tracking!N26/4-H$45)),ABS((Tracking!N26/4-H$48)))) | I62: =IF(Tracking!O26="","",IF(Person!$C$20="m",ABS((Tracking!O26/4-I$45)),ABS((Tracking!O26/4-I$48)))) | J62: =IF(Tracking!P26="","",IF(Person!$C$20="m",ABS((Tracking!P26/4-J$45)),ABS((Tracking!P26/4-J$48)))) | K62: =IF(Tracking!Q26="","",IF(Person!$C$20="m",ABS((Tracking!Q26/4-K$45)),ABS((Tracking!Q26/4-K$48)))) | ... P62: =IF(Tracking!V26="","",IF(Person!$C$20="m",ABS((Tracking!V26/4-P$45)),ABS((Tracking!V26/4-P$48)))) | R62: =IF(ISERROR(LARGE($D62:$P62,R$44)),"",LARGE($D62:$P62,R$44)) | S62: =IF(ISERROR(LARGE($D62:$P62,S$44)),"",LARGE($D62:$P62,S$44)) | T62: =IF(ISERROR(LARGE($D62:$P62,T$44)),"",LARGE($D62:$P62,T$44)) | U62: =IF(ISERROR(LARGE($D62:$P62,U$44)),"",LARGE($D62:$P62,U$44)) | V62: =IF(ISERROR(LARGE($D62:$P62,V$44)),"",LARGE($D62:$P62,V$44)) | W62: =IF(ISERROR(LARGE($D62:$P62,W$44)),"",LARGE($D62:$P62,W$44)) | X62: =IF(ISERROR(LARGE($D62:$P62,X$44)),"",LARGE($D62:$P62,X$44)) | Y62: =IF(ISERROR(LARGE($D62:$P62,Y$44)),"",LARGE($D62:$P62,Y$44)) | ... AD62: =IF(ISERROR(LARGE($D62:$P62,AD$44)),"",LARGE($D62:$P62,AD$44))
D63: =IF(D62="","",IF(D62=$R62,1,IF(D62=$S62,2,IF(D62=$T62,3,IF(D62=$U62,4,IF(D62=$V62,5,IF(D62=$W62,6,IF(D62=$X62,7,IF(D62=$Y62,8,IF(D62=$Z62,9,IF(D62=$AA62,10,IF(D62=$AB62,11,IF(D62=$AC62,12,IF(D62=$AD62,13)))))))))))))) | E63: =IF(E62="","",IF(E62=$R62,1,IF(E62=$S62,2,IF(E62=$T62,3,IF(E62=$U62,4,IF(E62=$V62,5,IF(E62=$W62,6,IF(E62=$X62,7,IF(E62=$Y62,8,IF(E62=$Z62,9,IF(E62=$AA62,10,IF(E62=$AB62,11,IF(E62=$AC62,12,IF(E62=$AD62,13)))))))))))))) | F63: =IF(F62="","",IF(F62=$R62,1,IF(F62=$S62,2,IF(F62=$T62,3,IF(F62=$U62,4,IF(F62=$V62,5,IF(F62=$W62,6,IF(F62=$X62,7,IF(F62=$Y62,8,IF(F62=$Z62,9,IF(F62=$AA62,10,IF(F62=$AB62,11,IF(F62=$AC62,12,IF(F62=$AD62,13)))))))))))))) | G63: =IF(G62="","",IF(G62=$R62,1,IF(G62=$S62,2,IF(G62=$T62,3,IF(G62=$U62,4,IF(G62=$V62,5,IF(G62=$W62,6,IF(G62=$X62,7,IF(G62=$Y62,8,IF(G62=$Z62,9,IF(G62=$AA62,10,IF(G62=$AB62,11,IF(G62=$AC62,12,IF(G62=$AD62,13)))))))))))))) | H63: =IF(H62="","",IF(H62=$R62,1,IF(H62=$S62,2,IF(H62=$T62,3,IF(H62=$U62,4,IF(H62=$V62,5,IF(H62=$W62,6,IF(H62=$X62,7,IF(H62=$Y62,8,IF(H62=$Z62,9,IF(H62=$AA62,10,IF(H62=$AB62,11,IF(H62=$AC62,12,IF(H62=$AD62,13)))))))))))))) | I63: =IF(I62="","",IF(I62=$R62,1,IF(I62=$S62,2,IF(I62=$T62,3,IF(I62=$U62,4,IF(I62=$V62,5,IF(I62=$W62,6,IF(I62=$X62,7,IF(I62=$Y62,8,IF(I62=$Z62,9,IF(I62=$AA62,10,IF(I62=$AB62,11,IF(I62=$AC62,12,IF(I62=$AD62,13)))))))))))))) | J63: =IF(J62="","",IF(J62=$R62,1,IF(J62=$S62,2,IF(J62=$T62,3,IF(J62=$U62,4,IF(J62=$V62,5,IF(J62=$W62,6,IF(J62=$X62,7,IF(J62=$Y62,8,IF(J62=$Z62,9,IF(J62=$AA62,10,IF(J62=$AB62,11,IF(J62=$AC62,12,IF(J62=$AD62,13)))))))))))))) | K63: =IF(K62="","",IF(K62=$R62,1,IF(K62=$S62,2,IF(K62=$T62,3,IF(K62=$U62,4,IF(K62=$V62,5,IF(K62=$W62,6,IF(K62=$X62,7,IF(K62=$Y62,8,IF(K62=$Z62,9,IF(K62=$AA62,10,IF(K62=$AB62,11,IF(K62=$AC62,12,IF(K62=$AD62,13)))))))))))))) | ... P63: =IF(P62="","",IF(P62=$R62,1,IF(P62=$S62,2,IF(P62=$T62,3,IF(P62=$U62,4,IF(P62=$V62,5,IF(P62=$W62,6,IF(P62=$X62,7,IF(P62=$Y62,8,IF(P62=$Z62,9,IF(P62=$AA62,10,IF(P62=$AB62,11,IF(P62=$AC62,12,IF(P62=$AD62,13))))))))))))))
D64: =IF(Tracking!J28="","",IF(Person!$C$20="m",ABS((Tracking!J28/4-D$45)),ABS((Tracking!J28/4-D$48)))) | E64: =IF(Tracking!K28="","",IF(Person!$C$20="m",ABS((Tracking!K28/4-E$45)),ABS((Tracking!K28/4-E$48)))) | F64: =IF(Tracking!L28="","",IF(Person!$C$20="m",ABS((Tracking!L28/4-F$45)),ABS((Tracking!L28/4-F$48)))) | G64: =IF(Tracking!M28="","",IF(Person!$C$20="m",ABS((Tracking!M28/4-G$45)),ABS((Tracking!M28/4-G$48)))) | H64: =IF(Tracking!N28="","",IF(Person!$C$20="m",ABS((Tracking!N28/4-H$45)),ABS((Tracking!N28/4-H$48)))) | I64: =IF(Tracking!O28="","",IF(Person!$C$20="m",ABS((Tracking!O28/4-I$45)),ABS((Tracking!O28/4-I$48)))) | J64: =IF(Tracking!P28="","",IF(Person!$C$20="m",ABS((Tracking!P28/4-J$45)),ABS((Tracking!P28/4-J$48)))) | K64: =IF(Tracking!Q28="","",IF(Person!$C$20="m",ABS((Tracking!Q28/4-K$45)),ABS((Tracking!Q28/4-K$48)))) | ... P64: =IF(Tracking!V28="","",IF(Person!$C$20="m",ABS((Tracking!V28/4-P$45)),ABS((Tracking!V28/4-P$48)))) | R64: =IF(ISERROR(LARGE($D64:$P64,R$44)),"",LARGE($D64:$P64,R$44)) | S64: =IF(ISERROR(LARGE($D64:$P64,S$44)),"",LARGE($D64:$P64,S$44)) | T64: =IF(ISERROR(LARGE($D64:$P64,T$44)),"",LARGE($D64:$P64,T$44)) | U64: =IF(ISERROR(LARGE($D64:$P64,U$44)),"",LARGE($D64:$P64,U$44)) | V64: =IF(ISERROR(LARGE($D64:$P64,V$44)),"",LARGE($D64:$P64,V$44)) | W64: =IF(ISERROR(LARGE($D64:$P64,W$44)),"",LARGE($D64:$P64,W$44)) | X64: =IF(ISERROR(LARGE($D64:$P64,X$44)),"",LARGE($D64:$P64,X$44)) | Y64: =IF(ISERROR(LARGE($D64:$P64,Y$44)),"",LARGE($D64:$P64,Y$44)) | ... AD64: =IF(ISERROR(LARGE($D64:$P64,AD$44)),"",LARGE($D64:$P64,AD$44))
D65: =IF(D64="","",IF(D64=$R64,1,IF(D64=$S64,2,IF(D64=$T64,3,IF(D64=$U64,4,IF(D64=$V64,5,IF(D64=$W64,6,IF(D64=$X64,7,IF(D64=$Y64,8,IF(D64=$Z64,9,IF(D64=$AA64,10,IF(D64=$AB64,11,IF(D64=$AC64,12,IF(D64=$AD64,13)))))))))))))) | E65: =IF(E64="","",IF(E64=$R64,1,IF(E64=$S64,2,IF(E64=$T64,3,IF(E64=$U64,4,IF(E64=$V64,5,IF(E64=$W64,6,IF(E64=$X64,7,IF(E64=$Y64,8,IF(E64=$Z64,9,IF(E64=$AA64,10,IF(E64=$AB64,11,IF(E64=$AC64,12,IF(E64=$AD64,13)))))))))))))) | F65: =IF(F64="","",IF(F64=$R64,1,IF(F64=$S64,2,IF(F64=$T64,3,IF(F64=$U64,4,IF(F64=$V64,5,IF(F64=$W64,6,IF(F64=$X64,7,IF(F64=$Y64,8,IF(F64=$Z64,9,IF(F64=$AA64,10,IF(F64=$AB64,11,IF(F64=$AC64,12,IF(F64=$AD64,13)))))))))))))) | G65: =IF(G64="","",IF(G64=$R64,1,IF(G64=$S64,2,IF(G64=$T64,3,IF(G64=$U64,4,IF(G64=$V64,5,IF(G64=$W64,6,IF(G64=$X64,7,IF(G64=$Y64,8,IF(G64=$Z64,9,IF(G64=$AA64,10,IF(G64=$AB64,11,IF(G64=$AC64,12,IF(G64=$AD64,13)))))))))))))) | H65: =IF(H64="","",IF(H64=$R64,1,IF(H64=$S64,2,IF(H64=$T64,3,IF(H64=$U64,4,IF(H64=$V64,5,IF(H64=$W64,6,IF(H64=$X64,7,IF(H64=$Y64,8,IF(H64=$Z64,9,IF(H64=$AA64,10,IF(H64=$AB64,11,IF(H64=$AC64,12,IF(H64=$AD64,13)))))))))))))) | I65: =IF(I64="","",IF(I64=$R64,1,IF(I64=$S64,2,IF(I64=$T64,3,IF(I64=$U64,4,IF(I64=$V64,5,IF(I64=$W64,6,IF(I64=$X64,7,IF(I64=$Y64,8,IF(I64=$Z64,9,IF(I64=$AA64,10,IF(I64=$AB64,11,IF(I64=$AC64,12,IF(I64=$AD64,13)))))))))))))) | J65: =IF(J64="","",IF(J64=$R64,1,IF(J64=$S64,2,IF(J64=$T64,3,IF(J64=$U64,4,IF(J64=$V64,5,IF(J64=$W64,6,IF(J64=$X64,7,IF(J64=$Y64,8,IF(J64=$Z64,9,IF(J64=$AA64,10,IF(J64=$AB64,11,IF(J64=$AC64,12,IF(J64=$AD64,13)))))))))))))) | K65: =IF(K64="","",IF(K64=$R64,1,IF(K64=$S64,2,IF(K64=$T64,3,IF(K64=$U64,4,IF(K64=$V64,5,IF(K64=$W64,6,IF(K64=$X64,7,IF(K64=$Y64,8,IF(K64=$Z64,9,IF(K64=$AA64,10,IF(K64=$AB64,11,IF(K64=$AC64,12,IF(K64=$AD64,13)))))))))))))) | ... P65: =IF(P64="","",IF(P64=$R64,1,IF(P64=$S64,2,IF(P64=$T64,3,IF(P64=$U64,4,IF(P64=$V64,5,IF(P64=$W64,6,IF(P64=$X64,7,IF(P64=$Y64,8,IF(P64=$Z64,9,IF(P64=$AA64,10,IF(P64=$AB64,11,IF(P64=$AC64,12,IF(P64=$AD64,13))))))))))))))
D66: =IF(Tracking!J30="","",IF(Person!$C$20="m",ABS((Tracking!J30/4-D$45)),ABS((Tracking!J30/4-D$48)))) | E66: =IF(Tracking!K30="","",IF(Person!$C$20="m",ABS((Tracking!K30/4-E$45)),ABS((Tracking!K30/4-E$48)))) | F66: =IF(Tracking!L30="","",IF(Person!$C$20="m",ABS((Tracking!L30/4-F$45)),ABS((Tracking!L30/4-F$48)))) | G66: =IF(Tracking!M30="","",IF(Person!$C$20="m",ABS((Tracking!M30/4-G$45)),ABS((Tracking!M30/4-G$48)))) | H66: =IF(Tracking!N30="","",IF(Person!$C$20="m",ABS((Tracking!N30/4-H$45)),ABS((Tracking!N30/4-H$48)))) | I66: =IF(Tracking!O30="","",IF(Person!$C$20="m",ABS((Tracking!O30/4-I$45)),ABS((Tracking!O30/4-I$48)))) | J66: =IF(Tracking!P30="","",IF(Person!$C$20="m",ABS((Tracking!P30/4-J$45)),ABS((Tracking!P30/4-J$48)))) | K66: =IF(Tracking!Q30="","",IF(Person!$C$20="m",ABS((Tracking!Q30/4-K$45)),ABS((Tracking!Q30/4-K$48)))) | ... P66: =IF(Tracking!V30="","",IF(Person!$C$20="m",ABS((Tracking!V30/4-P$45)),ABS((Tracking!V30/4-P$48)))) | R66: =IF(ISERROR(LARGE($D66:$P66,R$44)),"",LARGE($D66:$P66,R$44)) | S66: =IF(ISERROR(LARGE($D66:$P66,S$44)),"",LARGE($D66:$P66,S$44)) | T66: =IF(ISERROR(LARGE($D66:$P66,T$44)),"",LARGE($D66:$P66,T$44)) | U66: =IF(ISERROR(LARGE($D66:$P66,U$44)),"",LARGE($D66:$P66,U$44)) | V66: =IF(ISERROR(LARGE($D66:$P66,V$44)),"",LARGE($D66:$P66,V$44)) | W66: =IF(ISERROR(LARGE($D66:$P66,W$44)),"",LARGE($D66:$P66,W$44)) | X66: =IF(ISERROR(LARGE($D66:$P66,X$44)),"",LARGE($D66:$P66,X$44)) | Y66: =IF(ISERROR(LARGE($D66:$P66,Y$44)),"",LARGE($D66:$P66,Y$44)) | ... AD66: =IF(ISERROR(LARGE($D66:$P66,AD$44)),"",LARGE($D66:$P66,AD$44))
D67: =IF(D66="","",IF(D66=$R66,1,IF(D66=$S66,2,IF(D66=$T66,3,IF(D66=$U66,4,IF(D66=$V66,5,IF(D66=$W66,6,IF(D66=$X66,7,IF(D66=$Y66,8,IF(D66=$Z66,9,IF(D66=$AA66,10,IF(D66=$AB66,11,IF(D66=$AC66,12,IF(D66=$AD66,13)))))))))))))) | E67: =IF(E66="","",IF(E66=$R66,1,IF(E66=$S66,2,IF(E66=$T66,3,IF(E66=$U66,4,IF(E66=$V66,5,IF(E66=$W66,6,IF(E66=$X66,7,IF(E66=$Y66,8,IF(E66=$Z66,9,IF(E66=$AA66,10,IF(E66=$AB66,11,IF(E66=$AC66,12,IF(E66=$AD66,13)))))))))))))) | F67: =IF(F66="","",IF(F66=$R66,1,IF(F66=$S66,2,IF(F66=$T66,3,IF(F66=$U66,4,IF(F66=$V66,5,IF(F66=$W66,6,IF(F66=$X66,7,IF(F66=$Y66,8,IF(F66=$Z66,9,IF(F66=$AA66,10,IF(F66=$AB66,11,IF(F66=$AC66,12,IF(F66=$AD66,13)))))))))))))) | G67: =IF(G66="","",IF(G66=$R66,1,IF(G66=$S66,2,IF(G66=$T66,3,IF(G66=$U66,4,IF(G66=$V66,5,IF(G66=$W66,6,IF(G66=$X66,7,IF(G66=$Y66,8,IF(G66=$Z66,9,IF(G66=$AA66,10,IF(G66=$AB66,11,IF(G66=$AC66,12,IF(G66=$AD66,13)))))))))))))) | H67: =IF(H66="","",IF(H66=$R66,1,IF(H66=$S66,2,IF(H66=$T66,3,IF(H66=$U66,4,IF(H66=$V66,5,IF(H66=$W66,6,IF(H66=$X66,7,IF(H66=$Y66,8,IF(H66=$Z66,9,IF(H66=$AA66,10,IF(H66=$AB66,11,IF(H66=$AC66,12,IF(H66=$AD66,13)))))))))))))) | I67: =IF(I66="","",IF(I66=$R66,1,IF(I66=$S66,2,IF(I66=$T66,3,IF(I66=$U66,4,IF(I66=$V66,5,IF(I66=$W66,6,IF(I66=$X66,7,IF(I66=$Y66,8,IF(I66=$Z66,9,IF(I66=$AA66,10,IF(I66=$AB66,11,IF(I66=$AC66,12,IF(I66=$AD66,13)))))))))))))) | J67: =IF(J66="","",IF(J66=$R66,1,IF(J66=$S66,2,IF(J66=$T66,3,IF(J66=$U66,4,IF(J66=$V66,5,IF(J66=$W66,6,IF(J66=$X66,7,IF(J66=$Y66,8,IF(J66=$Z66,9,IF(J66=$AA66,10,IF(J66=$AB66,11,IF(J66=$AC66,12,IF(J66=$AD66,13)))))))))))))) | K67: =IF(K66="","",IF(K66=$R66,1,IF(K66=$S66,2,IF(K66=$T66,3,IF(K66=$U66,4,IF(K66=$V66,5,IF(K66=$W66,6,IF(K66=$X66,7,IF(K66=$Y66,8,IF(K66=$Z66,9,IF(K66=$AA66,10,IF(K66=$AB66,11,IF(K66=$AC66,12,IF(K66=$AD66,13)))))))))))))) | ... P67: =IF(P66="","",IF(P66=$R66,1,IF(P66=$S66,2,IF(P66=$T66,3,IF(P66=$U66,4,IF(P66=$V66,5,IF(P66=$W66,6,IF(P66=$X66,7,IF(P66=$Y66,8,IF(P66=$Z66,9,IF(P66=$AA66,10,IF(P66=$AB66,11,IF(P66=$AC66,12,IF(P66=$AD66,13))))))))))))))
D68: =IF(Tracking!J32="","",IF(Person!$C$20="m",ABS((Tracking!J32/4-D$45)),ABS((Tracking!J32/4-D$48)))) | E68: =IF(Tracking!K32="","",IF(Person!$C$20="m",ABS((Tracking!K32/4-E$45)),ABS((Tracking!K32/4-E$48)))) | F68: =IF(Tracking!L32="","",IF(Person!$C$20="m",ABS((Tracking!L32/4-F$45)),ABS((Tracking!L32/4-F$48)))) | G68: =IF(Tracking!M32="","",IF(Person!$C$20="m",ABS((Tracking!M32/4-G$45)),ABS((Tracking!M32/4-G$48)))) | H68: =IF(Tracking!N32="","",IF(Person!$C$20="m",ABS((Tracking!N32/4-H$45)),ABS((Tracking!N32/4-H$48)))) | I68: =IF(Tracking!O32="","",IF(Person!$C$20="m",ABS((Tracking!O32/4-I$45)),ABS((Tracking!O32/4-I$48)))) | J68: =IF(Tracking!P32="","",IF(Person!$C$20="m",ABS((Tracking!P32/4-J$45)),ABS((Tracking!P32/4-J$48)))) | K68: =IF(Tracking!Q32="","",IF(Person!$C$20="m",ABS((Tracking!Q32/4-K$45)),ABS((Tracking!Q32/4-K$48)))) | ... P68: =IF(Tracking!V32="","",IF(Person!$C$20="m",ABS((Tracking!V32/4-P$45)),ABS((Tracking!V32/4-P$48)))) | R68: =IF(ISERROR(LARGE($D68:$P68,R$44)),"",LARGE($D68:$P68,R$44)) | S68: =IF(ISERROR(LARGE($D68:$P68,S$44)),"",LARGE($D68:$P68,S$44)) | T68: =IF(ISERROR(LARGE($D68:$P68,T$44)),"",LARGE($D68:$P68,T$44)) | U68: =IF(ISERROR(LARGE($D68:$P68,U$44)),"",LARGE($D68:$P68,U$44)) | V68: =IF(ISERROR(LARGE($D68:$P68,V$44)),"",LARGE($D68:$P68,V$44)) | W68: =IF(ISERROR(LARGE($D68:$P68,W$44)),"",LARGE($D68:$P68,W$44)) | X68: =IF(ISERROR(LARGE($D68:$P68,X$44)),"",LARGE($D68:$P68,X$44)) | Y68: =IF(ISERROR(LARGE($D68:$P68,Y$44)),"",LARGE($D68:$P68,Y$44)) | ... AD68: =IF(ISERROR(LARGE($D68:$P68,AD$44)),"",LARGE($D68:$P68,AD$44))
D69: =IF(D68="","",IF(D68=$R68,1,IF(D68=$S68,2,IF(D68=$T68,3,IF(D68=$U68,4,IF(D68=$V68,5,IF(D68=$W68,6,IF(D68=$X68,7,IF(D68=$Y68,8,IF(D68=$Z68,9,IF(D68=$AA68,10,IF(D68=$AB68,11,IF(D68=$AC68,12,IF(D68=$AD68,13)))))))))))))) | E69: =IF(E68="","",IF(E68=$R68,1,IF(E68=$S68,2,IF(E68=$T68,3,IF(E68=$U68,4,IF(E68=$V68,5,IF(E68=$W68,6,IF(E68=$X68,7,IF(E68=$Y68,8,IF(E68=$Z68,9,IF(E68=$AA68,10,IF(E68=$AB68,11,IF(E68=$AC68,12,IF(E68=$AD68,13)))))))))))))) | F69: =IF(F68="","",IF(F68=$R68,1,IF(F68=$S68,2,IF(F68=$T68,3,IF(F68=$U68,4,IF(F68=$V68,5,IF(F68=$W68,6,IF(F68=$X68,7,IF(F68=$Y68,8,IF(F68=$Z68,9,IF(F68=$AA68,10,IF(F68=$AB68,11,IF(F68=$AC68,12,IF(F68=$AD68,13)))))))))))))) | G69: =IF(G68="","",IF(G68=$R68,1,IF(G68=$S68,2,IF(G68=$T68,3,IF(G68=$U68,4,IF(G68=$V68,5,IF(G68=$W68,6,IF(G68=$X68,7,IF(G68=$Y68,8,IF(G68=$Z68,9,IF(G68=$AA68,10,IF(G68=$AB68,11,IF(G68=$AC68,12,IF(G68=$AD68,13)))))))))))))) | H69: =IF(H68="","",IF(H68=$R68,1,IF(H68=$S68,2,IF(H68=$T68,3,IF(H68=$U68,4,IF(H68=$V68,5,IF(H68=$W68,6,IF(H68=$X68,7,IF(H68=$Y68,8,IF(H68=$Z68,9,IF(H68=$AA68,10,IF(H68=$AB68,11,IF(H68=$AC68,12,IF(H68=$AD68,13)))))))))))))) | I69: =IF(I68="","",IF(I68=$R68,1,IF(I68=$S68,2,IF(I68=$T68,3,IF(I68=$U68,4,IF(I68=$V68,5,IF(I68=$W68,6,IF(I68=$X68,7,IF(I68=$Y68,8,IF(I68=$Z68,9,IF(I68=$AA68,10,IF(I68=$AB68,11,IF(I68=$AC68,12,IF(I68=$AD68,13)))))))))))))) | J69: =IF(J68="","",IF(J68=$R68,1,IF(J68=$S68,2,IF(J68=$T68,3,IF(J68=$U68,4,IF(J68=$V68,5,IF(J68=$W68,6,IF(J68=$X68,7,IF(J68=$Y68,8,IF(J68=$Z68,9,IF(J68=$AA68,10,IF(J68=$AB68,11,IF(J68=$AC68,12,IF(J68=$AD68,13)))))))))))))) | K69: =IF(K68="","",IF(K68=$R68,1,IF(K68=$S68,2,IF(K68=$T68,3,IF(K68=$U68,4,IF(K68=$V68,5,IF(K68=$W68,6,IF(K68=$X68,7,IF(K68=$Y68,8,IF(K68=$Z68,9,IF(K68=$AA68,10,IF(K68=$AB68,11,IF(K68=$AC68,12,IF(K68=$AD68,13)))))))))))))) | ... P69: =IF(P68="","",IF(P68=$R68,1,IF(P68=$S68,2,IF(P68=$T68,3,IF(P68=$U68,4,IF(P68=$V68,5,IF(P68=$W68,6,IF(P68=$X68,7,IF(P68=$Y68,8,IF(P68=$Z68,9,IF(P68=$AA68,10,IF(P68=$AB68,11,IF(P68=$AC68,12,IF(P68=$AD68,13))))))))))))))
D70: =IF(Tracking!J34="","",IF(Person!$C$20="m",ABS((Tracking!J34/4-D$45)),ABS((Tracking!J34/4-D$48)))) | E70: =IF(Tracking!K34="","",IF(Person!$C$20="m",ABS((Tracking!K34/4-E$45)),ABS((Tracking!K34/4-E$48)))) | F70: =IF(Tracking!L34="","",IF(Person!$C$20="m",ABS((Tracking!L34/4-F$45)),ABS((Tracking!L34/4-F$48)))) | G70: =IF(Tracking!M34="","",IF(Person!$C$20="m",ABS((Tracking!M34/4-G$45)),ABS((Tracking!M34/4-G$48)))) | H70: =IF(Tracking!N34="","",IF(Person!$C$20="m",ABS((Tracking!N34/4-H$45)),ABS((Tracking!N34/4-H$48)))) | I70: =IF(Tracking!O34="","",IF(Person!$C$20="m",ABS((Tracking!O34/4-I$45)),ABS((Tracking!O34/4-I$48)))) | J70: =IF(Tracking!P34="","",IF(Person!$C$20="m",ABS((Tracking!P34/4-J$45)),ABS((Tracking!P34/4-J$48)))) | K70: =IF(Tracking!Q34="","",IF(Person!$C$20="m",ABS((Tracking!Q34/4-K$45)),ABS((Tracking!Q34/4-K$48)))) | ... P70: =IF(Tracking!V34="","",IF(Person!$C$20="m",ABS((Tracking!V34/4-P$45)),ABS((Tracking!V34/4-P$48)))) | R70: =IF(ISERROR(LARGE($D70:$P70,R$44)),"",LARGE($D70:$P70,R$44)) | S70: =IF(ISERROR(LARGE($D70:$P70,S$44)),"",LARGE($D70:$P70,S$44)) | T70: =IF(ISERROR(LARGE($D70:$P70,T$44)),"",LARGE($D70:$P70,T$44)) | U70: =IF(ISERROR(LARGE($D70:$P70,U$44)),"",LARGE($D70:$P70,U$44)) | V70: =IF(ISERROR(LARGE($D70:$P70,V$44)),"",LARGE($D70:$P70,V$44)) | W70: =IF(ISERROR(LARGE($D70:$P70,W$44)),"",LARGE($D70:$P70,W$44)) | X70: =IF(ISERROR(LARGE($D70:$P70,X$44)),"",LARGE($D70:$P70,X$44)) | Y70: =IF(ISERROR(LARGE($D70:$P70,Y$44)),"",LARGE($D70:$P70,Y$44)) | ... AD70: =IF(ISERROR(LARGE($D70:$P70,AD$44)),"",LARGE($D70:$P70,AD$44))
D71: =IF(D70="","",IF(D70=$R70,1,IF(D70=$S70,2,IF(D70=$T70,3,IF(D70=$U70,4,IF(D70=$V70,5,IF(D70=$W70,6,IF(D70=$X70,7,IF(D70=$Y70,8,IF(D70=$Z70,9,IF(D70=$AA70,10,IF(D70=$AB70,11,IF(D70=$AC70,12,IF(D70=$AD70,13)))))))))))))) | E71: =IF(E70="","",IF(E70=$R70,1,IF(E70=$S70,2,IF(E70=$T70,3,IF(E70=$U70,4,IF(E70=$V70,5,IF(E70=$W70,6,IF(E70=$X70,7,IF(E70=$Y70,8,IF(E70=$Z70,9,IF(E70=$AA70,10,IF(E70=$AB70,11,IF(E70=$AC70,12,IF(E70=$AD70,13)))))))))))))) | F71: =IF(F70="","",IF(F70=$R70,1,IF(F70=$S70,2,IF(F70=$T70,3,IF(F70=$U70,4,IF(F70=$V70,5,IF(F70=$W70,6,IF(F70=$X70,7,IF(F70=$Y70,8,IF(F70=$Z70,9,IF(F70=$AA70,10,IF(F70=$AB70,11,IF(F70=$AC70,12,IF(F70=$AD70,13)))))))))))))) | G71: =IF(G70="","",IF(G70=$R70,1,IF(G70=$S70,2,IF(G70=$T70,3,IF(G70=$U70,4,IF(G70=$V70,5,IF(G70=$W70,6,IF(G70=$X70,7,IF(G70=$Y70,8,IF(G70=$Z70,9,IF(G70=$AA70,10,IF(G70=$AB70,11,IF(G70=$AC70,12,IF(G70=$AD70,13)))))))))))))) | H71: =IF(H70="","",IF(H70=$R70,1,IF(H70=$S70,2,IF(H70=$T70,3,IF(H70=$U70,4,IF(H70=$V70,5,IF(H70=$W70,6,IF(H70=$X70,7,IF(H70=$Y70,8,IF(H70=$Z70,9,IF(H70=$AA70,10,IF(H70=$AB70,11,IF(H70=$AC70,12,IF(H70=$AD70,13)))))))))))))) | I71: =IF(I70="","",IF(I70=$R70,1,IF(I70=$S70,2,IF(I70=$T70,3,IF(I70=$U70,4,IF(I70=$V70,5,IF(I70=$W70,6,IF(I70=$X70,7,IF(I70=$Y70,8,IF(I70=$Z70,9,IF(I70=$AA70,10,IF(I70=$AB70,11,IF(I70=$AC70,12,IF(I70=$AD70,13)))))))))))))) | J71: =IF(J70="","",IF(J70=$R70,1,IF(J70=$S70,2,IF(J70=$T70,3,IF(J70=$U70,4,IF(J70=$V70,5,IF(J70=$W70,6,IF(J70=$X70,7,IF(J70=$Y70,8,IF(J70=$Z70,9,IF(J70=$AA70,10,IF(J70=$AB70,11,IF(J70=$AC70,12,IF(J70=$AD70,13)))))))))))))) | K71: =IF(K70="","",IF(K70=$R70,1,IF(K70=$S70,2,IF(K70=$T70,3,IF(K70=$U70,4,IF(K70=$V70,5,IF(K70=$W70,6,IF(K70=$X70,7,IF(K70=$Y70,8,IF(K70=$Z70,9,IF(K70=$AA70,10,IF(K70=$AB70,11,IF(K70=$AC70,12,IF(K70=$AD70,13)))))))))))))) | ... P71: =IF(P70="","",IF(P70=$R70,1,IF(P70=$S70,2,IF(P70=$T70,3,IF(P70=$U70,4,IF(P70=$V70,5,IF(P70=$W70,6,IF(P70=$X70,7,IF(P70=$Y70,8,IF(P70=$Z70,9,IF(P70=$AA70,10,IF(P70=$AB70,11,IF(P70=$AC70,12,IF(P70=$AD70,13))))))))))))))
D72: =IF(Tracking!J36="","",IF(Person!$C$20="m",ABS((Tracking!J36/4-D$45)),ABS((Tracking!J36/4-D$48)))) | E72: =IF(Tracking!K36="","",IF(Person!$C$20="m",ABS((Tracking!K36/4-E$45)),ABS((Tracking!K36/4-E$48)))) | F72: =IF(Tracking!L36="","",IF(Person!$C$20="m",ABS((Tracking!L36/4-F$45)),ABS((Tracking!L36/4-F$48)))) | G72: =IF(Tracking!M36="","",IF(Person!$C$20="m",ABS((Tracking!M36/4-G$45)),ABS((Tracking!M36/4-G$48)))) | H72: =IF(Tracking!N36="","",IF(Person!$C$20="m",ABS((Tracking!N36/4-H$45)),ABS((Tracking!N36/4-H$48)))) | I72: =IF(Tracking!O36="","",IF(Person!$C$20="m",ABS((Tracking!O36/4-I$45)),ABS((Tracking!O36/4-I$48)))) | J72: =IF(Tracking!P36="","",IF(Person!$C$20="m",ABS((Tracking!P36/4-J$45)),ABS((Tracking!P36/4-J$48)))) | K72: =IF(Tracking!Q36="","",IF(Person!$C$20="m",ABS((Tracking!Q36/4-K$45)),ABS((Tracking!Q36/4-K$48)))) | ... P72: =IF(Tracking!V36="","",IF(Person!$C$20="m",ABS((Tracking!V36/4-P$45)),ABS((Tracking!V36/4-P$48)))) | R72: =IF(ISERROR(LARGE($D72:$P72,R$44)),"",LARGE($D72:$P72,R$44)) | S72: =IF(ISERROR(LARGE($D72:$P72,S$44)),"",LARGE($D72:$P72,S$44)) | T72: =IF(ISERROR(LARGE($D72:$P72,T$44)),"",LARGE($D72:$P72,T$44)) | U72: =IF(ISERROR(LARGE($D72:$P72,U$44)),"",LARGE($D72:$P72,U$44)) | V72: =IF(ISERROR(LARGE($D72:$P72,V$44)),"",LARGE($D72:$P72,V$44)) | W72: =IF(ISERROR(LARGE($D72:$P72,W$44)),"",LARGE($D72:$P72,W$44)) | X72: =IF(ISERROR(LARGE($D72:$P72,X$44)),"",LARGE($D72:$P72,X$44)) | Y72: =IF(ISERROR(LARGE($D72:$P72,Y$44)),"",LARGE($D72:$P72,Y$44)) | ... AD72: =IF(ISERROR(LARGE($D72:$P72,AD$44)),"",LARGE($D72:$P72,AD$44))
D73: =IF(D72="","",IF(D72=$R72,1,IF(D72=$S72,2,IF(D72=$T72,3,IF(D72=$U72,4,IF(D72=$V72,5,IF(D72=$W72,6,IF(D72=$X72,7,IF(D72=$Y72,8,IF(D72=$Z72,9,IF(D72=$AA72,10,IF(D72=$AB72,11,IF(D72=$AC72,12,IF(D72=$AD72,13)))))))))))))) | E73: =IF(E72="","",IF(E72=$R72,1,IF(E72=$S72,2,IF(E72=$T72,3,IF(E72=$U72,4,IF(E72=$V72,5,IF(E72=$W72,6,IF(E72=$X72,7,IF(E72=$Y72,8,IF(E72=$Z72,9,IF(E72=$AA72,10,IF(E72=$AB72,11,IF(E72=$AC72,12,IF(E72=$AD72,13)))))))))))))) | F73: =IF(F72="","",IF(F72=$R72,1,IF(F72=$S72,2,IF(F72=$T72,3,IF(F72=$U72,4,IF(F72=$V72,5,IF(F72=$W72,6,IF(F72=$X72,7,IF(F72=$Y72,8,IF(F72=$Z72,9,IF(F72=$AA72,10,IF(F72=$AB72,11,IF(F72=$AC72,12,IF(F72=$AD72,13)))))))))))))) | G73: =IF(G72="","",IF(G72=$R72,1,IF(G72=$S72,2,IF(G72=$T72,3,IF(G72=$U72,4,IF(G72=$V72,5,IF(G72=$W72,6,IF(G72=$X72,7,IF(G72=$Y72,8,IF(G72=$Z72,9,IF(G72=$AA72,10,IF(G72=$AB72,11,IF(G72=$AC72,12,IF(G72=$AD72,13)))))))))))))) | H73: =IF(H72="","",IF(H72=$R72,1,IF(H72=$S72,2,IF(H72=$T72,3,IF(H72=$U72,4,IF(H72=$V72,5,IF(H72=$W72,6,IF(H72=$X72,7,IF(H72=$Y72,8,IF(H72=$Z72,9,IF(H72=$AA72,10,IF(H72=$AB72,11,IF(H72=$AC72,12,IF(H72=$AD72,13)))))))))))))) | I73: =IF(I72="","",IF(I72=$R72,1,IF(I72=$S72,2,IF(I72=$T72,3,IF(I72=$U72,4,IF(I72=$V72,5,IF(I72=$W72,6,IF(I72=$X72,7,IF(I72=$Y72,8,IF(I72=$Z72,9,IF(I72=$AA72,10,IF(I72=$AB72,11,IF(I72=$AC72,12,IF(I72=$AD72,13)))))))))))))) | J73: =IF(J72="","",IF(J72=$R72,1,IF(J72=$S72,2,IF(J72=$T72,3,IF(J72=$U72,4,IF(J72=$V72,5,IF(J72=$W72,6,IF(J72=$X72,7,IF(J72=$Y72,8,IF(J72=$Z72,9,IF(J72=$AA72,10,IF(J72=$AB72,11,IF(J72=$AC72,12,IF(J72=$AD72,13)))))))))))))) | K73: =IF(K72="","",IF(K72=$R72,1,IF(K72=$S72,2,IF(K72=$T72,3,IF(K72=$U72,4,IF(K72=$V72,5,IF(K72=$W72,6,IF(K72=$X72,7,IF(K72=$Y72,8,IF(K72=$Z72,9,IF(K72=$AA72,10,IF(K72=$AB72,11,IF(K72=$AC72,12,IF(K72=$AD72,13)))))))))))))) | ... P73: =IF(P72="","",IF(P72=$R72,1,IF(P72=$S72,2,IF(P72=$T72,3,IF(P72=$U72,4,IF(P72=$V72,5,IF(P72=$W72,6,IF(P72=$X72,7,IF(P72=$Y72,8,IF(P72=$Z72,9,IF(P72=$AA72,10,IF(P72=$AB72,11,IF(P72=$AC72,12,IF(P72=$AD72,13))))))))))))))
D74: =IF(Tracking!J38="","",IF(Person!$C$20="m",ABS((Tracking!J38/4-D$45)),ABS((Tracking!J38/4-D$48)))) | E74: =IF(Tracking!K38="","",IF(Person!$C$20="m",ABS((Tracking!K38/4-E$45)),ABS((Tracking!K38/4-E$48)))) | F74: =IF(Tracking!L38="","",IF(Person!$C$20="m",ABS((Tracking!L38/4-F$45)),ABS((Tracking!L38/4-F$48)))) | G74: =IF(Tracking!M38="","",IF(Person!$C$20="m",ABS((Tracking!M38/4-G$45)),ABS((Tracking!M38/4-G$48)))) | H74: =IF(Tracking!N38="","",IF(Person!$C$20="m",ABS((Tracking!N38/4-H$45)),ABS((Tracking!N38/4-H$48)))) | I74: =IF(Tracking!O38="","",IF(Person!$C$20="m",ABS((Tracking!O38/4-I$45)),ABS((Tracking!O38/4-I$48)))) | J74: =IF(Tracking!P38="","",IF(Person!$C$20="m",ABS((Tracking!P38/4-J$45)),ABS((Tracking!P38/4-J$48)))) | K74: =IF(Tracking!Q38="","",IF(Person!$C$20="m",ABS((Tracking!Q38/4-K$45)),ABS((Tracking!Q38/4-K$48)))) | ... P74: =IF(Tracking!V38="","",IF(Person!$C$20="m",ABS((Tracking!V38/4-P$45)),ABS((Tracking!V38/4-P$48)))) | R74: =IF(ISERROR(LARGE($D74:$P74,R$44)),"",LARGE($D74:$P74,R$44)) | S74: =IF(ISERROR(LARGE($D74:$P74,S$44)),"",LARGE($D74:$P74,S$44)) | T74: =IF(ISERROR(LARGE($D74:$P74,T$44)),"",LARGE($D74:$P74,T$44)) | U74: =IF(ISERROR(LARGE($D74:$P74,U$44)),"",LARGE($D74:$P74,U$44)) | V74: =IF(ISERROR(LARGE($D74:$P74,V$44)),"",LARGE($D74:$P74,V$44)) | W74: =IF(ISERROR(LARGE($D74:$P74,W$44)),"",LARGE($D74:$P74,W$44)) | X74: =IF(ISERROR(LARGE($D74:$P74,X$44)),"",LARGE($D74:$P74,X$44)) | Y74: =IF(ISERROR(LARGE($D74:$P74,Y$44)),"",LARGE($D74:$P74,Y$44)) | ... AD74: =IF(ISERROR(LARGE($D74:$P74,AD$44)),"",LARGE($D74:$P74,AD$44))
